/usr/local/usrapps/ddomlab/sdehgha2/pls-dataset-env/lib/python3.10/site-packages/joblib/externals/loky/process_executor.py:752: UserWarning: A worker stopped while some jobs were given to the executor. This can be caused by a too short worker timeout or by a memory leak.
  warnings.warn(
/usr/local/usrapps/ddomlab/sdehgha2/pls-dataset-env/lib/python3.10/site-packages/joblib/externals/loky/process_executor.py:752: UserWarning: A worker stopped while some jobs were given to the executor. This can be caused by a too short worker timeout or by a memory leak.
  warnings.warn(
Exception ignored in: <function Booster.__del__ at 0x14d70cf20670>
Traceback (most recent call last):
  File "/usr/local/usrapps/ddomlab/sdehgha2/pls-dataset-env/lib/python3.10/site-packages/xgboost/core.py", line 1797, in __del__
    _check_call(_LIB.XGBoosterFree(self.handle))
KeyboardInterrupt: 
Terminated
/usr/local/usrapps/ddomlab/sdehgha2/pls-dataset-env/lib/python3.10/site-packages/joblib/externals/loky/backend/resource_tracker.py:314: UserWarning: resource_tracker: There appear to be 74 leaked semlock objects to clean up at shutdown
  warnings.warn(
/usr/local/usrapps/ddomlab/sdehgha2/pls-dataset-env/lib/python3.10/site-packages/joblib/externals/loky/backend/resource_tracker.py:314: UserWarning: resource_tracker: There appear to be 21 leaked folder objects to clean up at shutdown
  warnings.warn(
/usr/local/usrapps/ddomlab/sdehgha2/pls-dataset-env/lib/python3.10/site-packages/joblib/externals/loky/process_executor.py:752: UserWarning: A worker stopped while some jobs were given to the executor. This can be caused by a too short worker timeout or by a memory leak.
  warnings.warn(
Process LokyProcess-58:
Process LokyProcess-66:
Process LokyProcess-42:
Process LokyProcess-57:
Process LokyProcess-38:
Process LokyProcess-40:
Process LokyProcess-41:
Process LokyProcess-73:
Process LokyProcess-46:
Traceback (most recent call last):
  File "/usr/local/usrapps/ddomlab/sdehgha2/pls-dataset-env/lib/python3.10/site-packages/joblib/externals/loky/process_executor.py", line 426, in _process_worker
    call_item = call_queue.get(block=True, timeout=timeout)
  File "/usr/local/usrapps/ddomlab/sdehgha2/pls-dataset-env/lib/python3.10/multiprocessing/queues.py", line 108, in get
    if not self._rlock.acquire(block, timeout):
KeyboardInterrupt

During handling of the above exception, another exception occurred:

Traceback (most recent call last):
  File "/usr/local/usrapps/ddomlab/sdehgha2/pls-dataset-env/lib/python3.10/multiprocessing/process.py", line 314, in _bootstrap
    self.run()
  File "/usr/local/usrapps/ddomlab/sdehgha2/pls-dataset-env/lib/python3.10/multiprocessing/process.py", line 108, in run
    self._target(*self._args, **self._kwargs)
  File "/usr/local/usrapps/ddomlab/sdehgha2/pls-dataset-env/lib/python3.10/site-packages/joblib/externals/loky/process_executor.py", line 426, in _process_worker
    call_item = call_queue.get(block=True, timeout=timeout)
KeyboardInterrupt
Traceback (most recent call last):
  File "/usr/local/usrapps/ddomlab/sdehgha2/pls-dataset-env/lib/python3.10/site-packages/joblib/parallel.py", line 1650, in _get_outputs
    yield from self._retrieve()
  File "/usr/local/usrapps/ddomlab/sdehgha2/pls-dataset-env/lib/python3.10/site-packages/joblib/parallel.py", line 1762, in _retrieve
    time.sleep(0.01)
KeyboardInterrupt

During handling of the above exception, another exception occurred:

Traceback (most recent call last):
  File "/gpfs_common/share03/ddomlab/sdehgha2/working-space/main/P1_pls-dataset/pls-dataset-space/PLS-Dataset/code_/training/hpc_submit_training_Rh/../make_ood_learning_curve.py", line 87, in <module>
    main_structural_numerical(
  File "/gpfs_common/share03/ddomlab/sdehgha2/working-space/main/P1_pls-dataset/pls-dataset-space/PLS-Dataset/code_/training/hpc_submit_training_Rh/../make_ood_learning_curve.py", line 46, in main_structural_numerical
    scores, predictions  = train_ood_learning_curve(
  File "/gpfs_common/share03/ddomlab/sdehgha2/working-space/main/P1_pls-dataset/pls-dataset-space/PLS-Dataset/code_/training/get_ood_split_learning_curve.py", line 64, in train_ood_learning_curve
    score, predictions = prepare_data(
  File "/gpfs_common/share03/ddomlab/sdehgha2/working-space/main/P1_pls-dataset/pls-dataset-space/PLS-Dataset/code_/training/get_ood_split_learning_curve.py", line 112, in prepare_data
    return run_ood_learning_curve(X, y,
  File "/gpfs_common/share03/ddomlab/sdehgha2/working-space/main/P1_pls-dataset/pls-dataset-space/PLS-Dataset/code_/training/get_ood_split_learning_curve.py", line 248, in run_ood_learning_curve
    ood_results = Parallel(n_jobs=n_jobs)(
  File "/usr/local/usrapps/ddomlab/sdehgha2/pls-dataset-env/lib/python3.10/site-packages/joblib/parallel.py", line 2007, in __call__
    return output if self.return_generator else list(output)
  File "/usr/local/usrapps/ddomlab/sdehgha2/pls-dataset-env/lib/python3.10/site-packages/joblib/parallel.py", line 1703, in _get_outputs
    self._abort()
  File "/usr/local/usrapps/ddomlab/sdehgha2/pls-dataset-env/lib/python3.10/site-packages/joblib/parallel.py", line 1614, in _abort
    backend.abort_everything(ensure_ready=ensure_ready)
  File "/usr/local/usrapps/ddomlab/sdehgha2/pls-dataset-env/lib/python3.10/site-packages/joblib/_parallel_backends.py", line 620, in abort_everything
Traceback (most recent call last):
Traceback (most recent call last):
Traceback (most recent call last):
  File "/usr/local/usrapps/ddomlab/sdehgha2/pls-dataset-env/lib/python3.10/site-packages/joblib/externals/loky/process_executor.py", line 426, in _process_worker
    call_item = call_queue.get(block=True, timeout=timeout)
Traceback (most recent call last):
Traceback (most recent call last):
  File "/usr/local/usrapps/ddomlab/sdehgha2/pls-dataset-env/lib/python3.10/site-packages/joblib/externals/loky/process_executor.py", line 426, in _process_worker
    call_item = call_queue.get(block=True, timeout=timeout)
  File "/usr/local/usrapps/ddomlab/sdehgha2/pls-dataset-env/lib/python3.10/multiprocessing/queues.py", line 108, in get
    if not self._rlock.acquire(block, timeout):
  File "/usr/local/usrapps/ddomlab/sdehgha2/pls-dataset-env/lib/python3.10/site-packages/joblib/externals/loky/process_executor.py", line 426, in _process_worker
    call_item = call_queue.get(block=True, timeout=timeout)
  File "/usr/local/usrapps/ddomlab/sdehgha2/pls-dataset-env/lib/python3.10/site-packages/joblib/externals/loky/process_executor.py", line 426, in _process_worker
    call_item = call_queue.get(block=True, timeout=timeout)
  File "/usr/local/usrapps/ddomlab/sdehgha2/pls-dataset-env/lib/python3.10/multiprocessing/queues.py", line 108, in get
    if not self._rlock.acquire(block, timeout):
  File "/usr/local/usrapps/ddomlab/sdehgha2/pls-dataset-env/lib/python3.10/site-packages/joblib/externals/loky/process_executor.py", line 426, in _process_worker
    call_item = call_queue.get(block=True, timeout=timeout)
KeyboardInterrupt
  File "/usr/local/usrapps/ddomlab/sdehgha2/pls-dataset-env/lib/python3.10/multiprocessing/queues.py", line 108, in get
    if not self._rlock.acquire(block, timeout):
  File "/usr/local/usrapps/ddomlab/sdehgha2/pls-dataset-env/lib/python3.10/multiprocessing/queues.py", line 108, in get
    if not self._rlock.acquire(block, timeout):
KeyboardInterrupt
  File "/usr/local/usrapps/ddomlab/sdehgha2/pls-dataset-env/lib/python3.10/multiprocessing/queues.py", line 108, in get
    if not self._rlock.acquire(block, timeout):

During handling of the above exception, another exception occurred:

Traceback (most recent call last):
KeyboardInterrupt
KeyboardInterrupt

During handling of the above exception, another exception occurred:

Traceback (most recent call last):
KeyboardInterrupt

During handling of the above exception, another exception occurred:


During handling of the above exception, another exception occurred:

  File "/usr/local/usrapps/ddomlab/sdehgha2/pls-dataset-env/lib/python3.10/site-packages/joblib/externals/loky/process_executor.py", line 426, in _process_worker
    call_item = call_queue.get(block=True, timeout=timeout)
Traceback (most recent call last):

During handling of the above exception, another exception occurred:

Traceback (most recent call last):
  File "/usr/local/usrapps/ddomlab/sdehgha2/pls-dataset-env/lib/python3.10/multiprocessing/process.py", line 314, in _bootstrap
    self.run()
Traceback (most recent call last):
  File "/usr/local/usrapps/ddomlab/sdehgha2/pls-dataset-env/lib/python3.10/multiprocessing/queues.py", line 108, in get
    if not self._rlock.acquire(block, timeout):
Traceback (most recent call last):
  File "/usr/local/usrapps/ddomlab/sdehgha2/pls-dataset-env/lib/python3.10/multiprocessing/process.py", line 314, in _bootstrap
    self.run()
  File "/usr/local/usrapps/ddomlab/sdehgha2/pls-dataset-env/lib/python3.10/multiprocessing/process.py", line 108, in run
    self._target(*self._args, **self._kwargs)
  File "/usr/local/usrapps/ddomlab/sdehgha2/pls-dataset-env/lib/python3.10/multiprocessing/process.py", line 314, in _bootstrap
    self.run()
KeyboardInterrupt
  File "/usr/local/usrapps/ddomlab/sdehgha2/pls-dataset-env/lib/python3.10/multiprocessing/process.py", line 314, in _bootstrap
    self.run()
  File "/usr/local/usrapps/ddomlab/sdehgha2/pls-dataset-env/lib/python3.10/multiprocessing/process.py", line 108, in run
    self._target(*self._args, **self._kwargs)
  File "/usr/local/usrapps/ddomlab/sdehgha2/pls-dataset-env/lib/python3.10/multiprocessing/process.py", line 314, in _bootstrap
    self.run()
  File "/usr/local/usrapps/ddomlab/sdehgha2/pls-dataset-env/lib/python3.10/site-packages/joblib/externals/loky/process_executor.py", line 438, in _process_worker
    previous_tb = traceback.format_exc()
  File "/usr/local/usrapps/ddomlab/sdehgha2/pls-dataset-env/lib/python3.10/multiprocessing/process.py", line 108, in run
    self._target(*self._args, **self._kwargs)

During handling of the above exception, another exception occurred:

  File "/usr/local/usrapps/ddomlab/sdehgha2/pls-dataset-env/lib/python3.10/multiprocessing/process.py", line 108, in run
    self._target(*self._args, **self._kwargs)
  File "/usr/local/usrapps/ddomlab/sdehgha2/pls-dataset-env/lib/python3.10/site-packages/joblib/externals/loky/process_executor.py", line 438, in _process_worker
    previous_tb = traceback.format_exc()
  File "/usr/local/usrapps/ddomlab/sdehgha2/pls-dataset-env/lib/python3.10/multiprocessing/process.py", line 108, in run
    self._target(*self._args, **self._kwargs)
  File "/usr/local/usrapps/ddomlab/sdehgha2/pls-dataset-env/lib/python3.10/traceback.py", line 183, in format_exc
    return "".join(format_exception(*sys.exc_info(), limit=limit, chain=chain))
  File "/usr/local/usrapps/ddomlab/sdehgha2/pls-dataset-env/lib/python3.10/site-packages/joblib/externals/loky/process_executor.py", line 438, in _process_worker
    previous_tb = traceback.format_exc()
Traceback (most recent call last):
  File "/usr/local/usrapps/ddomlab/sdehgha2/pls-dataset-env/lib/python3.10/site-packages/joblib/externals/loky/process_executor.py", line 438, in _process_worker
    previous_tb = traceback.format_exc()
  File "/usr/local/usrapps/ddomlab/sdehgha2/pls-dataset-env/lib/python3.10/traceback.py", line 183, in format_exc
    return "".join(format_exception(*sys.exc_info(), limit=limit, chain=chain))
  File "/usr/local/usrapps/ddomlab/sdehgha2/pls-dataset-env/lib/python3.10/site-packages/joblib/externals/loky/process_executor.py", line 438, in _process_worker
    previous_tb = traceback.format_exc()
  File "/usr/local/usrapps/ddomlab/sdehgha2/pls-dataset-env/lib/python3.10/traceback.py", line 135, in format_exception
    te = TracebackException(type(value), value, tb, limit=limit, compact=True)
  File "/usr/local/usrapps/ddomlab/sdehgha2/pls-dataset-env/lib/python3.10/traceback.py", line 183, in format_exc
    return "".join(format_exception(*sys.exc_info(), limit=limit, chain=chain))
  File "/usr/local/usrapps/ddomlab/sdehgha2/pls-dataset-env/lib/python3.10/traceback.py", line 183, in format_exc
    return "".join(format_exception(*sys.exc_info(), limit=limit, chain=chain))
  File "/usr/local/usrapps/ddomlab/sdehgha2/pls-dataset-env/lib/python3.10/traceback.py", line 135, in format_exception
    te = TracebackException(type(value), value, tb, limit=limit, compact=True)
  File "/usr/local/usrapps/ddomlab/sdehgha2/pls-dataset-env/lib/python3.10/multiprocessing/process.py", line 314, in _bootstrap
    self.run()
  File "/usr/local/usrapps/ddomlab/sdehgha2/pls-dataset-env/lib/python3.10/traceback.py", line 183, in format_exc
    return "".join(format_exception(*sys.exc_info(), limit=limit, chain=chain))
  File "/usr/local/usrapps/ddomlab/sdehgha2/pls-dataset-env/lib/python3.10/traceback.py", line 502, in __init__
    self.stack = StackSummary.extract(
  File "/usr/local/usrapps/ddomlab/sdehgha2/pls-dataset-env/lib/python3.10/traceback.py", line 135, in format_exception
    te = TracebackException(type(value), value, tb, limit=limit, compact=True)
  File "/usr/local/usrapps/ddomlab/sdehgha2/pls-dataset-env/lib/python3.10/traceback.py", line 135, in format_exception
    te = TracebackException(type(value), value, tb, limit=limit, compact=True)
  File "/usr/local/usrapps/ddomlab/sdehgha2/pls-dataset-env/lib/python3.10/traceback.py", line 503, in __init__
    walk_tb(exc_traceback), limit=limit, lookup_lines=lookup_lines,
  File "/usr/local/usrapps/ddomlab/sdehgha2/pls-dataset-env/lib/python3.10/multiprocessing/process.py", line 108, in run
    self._target(*self._args, **self._kwargs)
  File "/usr/local/usrapps/ddomlab/sdehgha2/pls-dataset-env/lib/python3.10/traceback.py", line 135, in format_exception
    te = TracebackException(type(value), value, tb, limit=limit, compact=True)
  File "/usr/local/usrapps/ddomlab/sdehgha2/pls-dataset-env/lib/python3.10/traceback.py", line 376, in extract
    result.append(FrameSummary(
Traceback (most recent call last):
  File "/usr/local/usrapps/ddomlab/sdehgha2/pls-dataset-env/lib/python3.10/traceback.py", line 502, in __init__
    self.stack = StackSummary.extract(
  File "/usr/local/usrapps/ddomlab/sdehgha2/pls-dataset-env/lib/python3.10/traceback.py", line 502, in __init__
    self.stack = StackSummary.extract(
KeyboardInterrupt
  File "/usr/local/usrapps/ddomlab/sdehgha2/pls-dataset-env/lib/python3.10/site-packages/joblib/externals/loky/process_executor.py", line 438, in _process_worker
    previous_tb = traceback.format_exc()
  File "/usr/local/usrapps/ddomlab/sdehgha2/pls-dataset-env/lib/python3.10/traceback.py", line 489, in __init__
    def __init__(self, exc_type, exc_value, exc_traceback, *, limit=None,
KeyboardInterrupt
  File "/usr/local/usrapps/ddomlab/sdehgha2/pls-dataset-env/lib/python3.10/traceback.py", line 353, in extract
    limit = getattr(sys, 'tracebacklimit', None)
  File "/usr/local/usrapps/ddomlab/sdehgha2/pls-dataset-env/lib/python3.10/site-packages/joblib/externals/loky/process_executor.py", line 426, in _process_worker
    call_item = call_queue.get(block=True, timeout=timeout)
  File "/usr/local/usrapps/ddomlab/sdehgha2/pls-dataset-env/lib/python3.10/traceback.py", line 376, in extract
    result.append(FrameSummary(
  File "/usr/local/usrapps/ddomlab/sdehgha2/pls-dataset-env/lib/python3.10/traceback.py", line 183, in format_exc
    return "".join(format_exception(*sys.exc_info(), limit=limit, chain=chain))
KeyboardInterrupt
KeyboardInterrupt
  File "/usr/local/usrapps/ddomlab/sdehgha2/pls-dataset-env/lib/python3.10/multiprocessing/queues.py", line 108, in get
    if not self._rlock.acquire(block, timeout):
  File "/usr/local/usrapps/ddomlab/sdehgha2/pls-dataset-env/lib/python3.10/traceback.py", line 274, in __init__
    if lookup_line:
  File "/usr/local/usrapps/ddomlab/sdehgha2/pls-dataset-env/lib/python3.10/traceback.py", line 135, in format_exception
    te = TracebackException(type(value), value, tb, limit=limit, compact=True)
KeyboardInterrupt
KeyboardInterrupt
  File "/usr/local/usrapps/ddomlab/sdehgha2/pls-dataset-env/lib/python3.10/traceback.py", line 502, in __init__
    self.stack = StackSummary.extract(

During handling of the above exception, another exception occurred:

  File "/usr/local/usrapps/ddomlab/sdehgha2/pls-dataset-env/lib/python3.10/traceback.py", line 353, in extract
    limit = getattr(sys, 'tracebacklimit', None)
Traceback (most recent call last):
KeyboardInterrupt
  File "/usr/local/usrapps/ddomlab/sdehgha2/pls-dataset-env/lib/python3.10/multiprocessing/process.py", line 314, in _bootstrap
    self.run()
  File "/usr/local/usrapps/ddomlab/sdehgha2/pls-dataset-env/lib/python3.10/multiprocessing/process.py", line 108, in run
    self._target(*self._args, **self._kwargs)
  File "/usr/local/usrapps/ddomlab/sdehgha2/pls-dataset-env/lib/python3.10/site-packages/joblib/externals/loky/process_executor.py", line 438, in _process_worker
    previous_tb = traceback.format_exc()
  File "/usr/local/usrapps/ddomlab/sdehgha2/pls-dataset-env/lib/python3.10/traceback.py", line 183, in format_exc
    return "".join(format_exception(*sys.exc_info(), limit=limit, chain=chain))
  File "/usr/local/usrapps/ddomlab/sdehgha2/pls-dataset-env/lib/python3.10/traceback.py", line 135, in format_exception
    te = TracebackException(type(value), value, tb, limit=limit, compact=True)
  File "/usr/local/usrapps/ddomlab/sdehgha2/pls-dataset-env/lib/python3.10/traceback.py", line 502, in __init__
    self.stack = StackSummary.extract(
  File "/usr/local/usrapps/ddomlab/sdehgha2/pls-dataset-env/lib/python3.10/traceback.py", line 376, in extract
    result.append(FrameSummary(
  File "/usr/local/usrapps/ddomlab/sdehgha2/pls-dataset-env/lib/python3.10/traceback.py", line 259, in __init__
    def __init__(self, filename, lineno, name, *, lookup_line=True,
KeyboardInterrupt
    self._workers.terminate(kill_workers=True)
  File "/usr/local/usrapps/ddomlab/sdehgha2/pls-dataset-env/lib/python3.10/site-packages/joblib/executor.py", line 75, in terminate
    self.shutdown(kill_workers=kill_workers)
  File "/usr/local/usrapps/ddomlab/sdehgha2/pls-dataset-env/lib/python3.10/site-packages/joblib/externals/loky/process_executor.py", line 1297, in shutdown
    self._executor_manager_thread_wakeup.wakeup()
  File "/usr/local/usrapps/ddomlab/sdehgha2/pls-dataset-env/lib/python3.10/site-packages/joblib/externals/loky/process_executor.py", line 132, in wakeup
    self._writer.send_bytes(b"")
  File "/usr/local/usrapps/ddomlab/sdehgha2/pls-dataset-env/lib/python3.10/multiprocessing/connection.py", line 185, in send_bytes
    m = memoryview(buf)
KeyboardInterrupt
Traceback (most recent call last):
  File "/usr/local/usrapps/ddomlab/sdehgha2/pls-dataset-env/lib/python3.10/site-packages/joblib/externals/loky/process_executor.py", line 426, in _process_worker
    call_item = call_queue.get(block=True, timeout=timeout)
  File "/usr/local/usrapps/ddomlab/sdehgha2/pls-dataset-env/lib/python3.10/multiprocessing/queues.py", line 113, in get
    if not self._poll(timeout):
  File "/usr/local/usrapps/ddomlab/sdehgha2/pls-dataset-env/lib/python3.10/multiprocessing/connection.py", line 257, in poll
    return self._poll(timeout)
  File "/usr/local/usrapps/ddomlab/sdehgha2/pls-dataset-env/lib/python3.10/multiprocessing/connection.py", line 424, in _poll
    r = wait([self], timeout)
  File "/usr/local/usrapps/ddomlab/sdehgha2/pls-dataset-env/lib/python3.10/multiprocessing/connection.py", line 931, in wait
    ready = selector.select(timeout)
  File "/usr/local/usrapps/ddomlab/sdehgha2/pls-dataset-env/lib/python3.10/selectors.py", line 416, in select
    fd_event_list = self._selector.poll(timeout)
KeyboardInterrupt

During handling of the above exception, another exception occurred:

Traceback (most recent call last):
  File "/usr/local/usrapps/ddomlab/sdehgha2/pls-dataset-env/lib/python3.10/multiprocessing/process.py", line 314, in _bootstrap
    self.run()
  File "/usr/local/usrapps/ddomlab/sdehgha2/pls-dataset-env/lib/python3.10/multiprocessing/process.py", line 108, in run
    self._target(*self._args, **self._kwargs)
  File "/usr/local/usrapps/ddomlab/sdehgha2/pls-dataset-env/lib/python3.10/site-packages/joblib/externals/loky/process_executor.py", line 438, in _process_worker
    previous_tb = traceback.format_exc()
  File "/usr/local/usrapps/ddomlab/sdehgha2/pls-dataset-env/lib/python3.10/traceback.py", line 183, in format_exc
    return "".join(format_exception(*sys.exc_info(), limit=limit, chain=chain))
  File "/usr/local/usrapps/ddomlab/sdehgha2/pls-dataset-env/lib/python3.10/traceback.py", line 135, in format_exception
    te = TracebackException(type(value), value, tb, limit=limit, compact=True)
  File "/usr/local/usrapps/ddomlab/sdehgha2/pls-dataset-env/lib/python3.10/traceback.py", line 489, in __init__
    def __init__(self, exc_type, exc_value, exc_traceback, *, limit=None,
KeyboardInterrupt
/usr/local/usrapps/ddomlab/sdehgha2/pls-dataset-env/lib/python3.10/site-packages/joblib/externals/loky/backend/resource_tracker.py:314: UserWarning: resource_tracker: There appear to be 24 leaked semlock objects to clean up at shutdown
  warnings.warn(
/usr/local/usrapps/ddomlab/sdehgha2/pls-dataset-env/lib/python3.10/site-packages/joblib/externals/loky/process_executor.py:752: UserWarning: A worker stopped while some jobs were given to the executor. This can be caused by a too short worker timeout or by a memory leak.
  warnings.warn(
