/gpfs_common/share03/ddomlab/sdehgha2/working-space/main/P1_pls-dataset/pls-dataset-space/PLS-Dataset/code_/training/scoring.py:70: ConstantInputWarning: An input array is constant; the correlation coefficient is not defined.
  r = pearsonr(y_true, y_pred)[0]
Process LokyProcess-5:
Process LokyProcess-9:
Process LokyProcess-3:
Process LokyProcess-2:
Process LokyProcess-15:
Process LokyProcess-8:
Traceback (most recent call last):
  File "/usr/local/usrapps/ddomlab/sdehgha2/pls-dataset-env/lib/python3.10/site-packages/sklearn/model_selection/_search.py", line 1019, in fit
Traceback (most recent call last):
  File "/usr/local/usrapps/ddomlab/sdehgha2/pls-dataset-env/lib/python3.10/site-packages/joblib/externals/loky/process_executor.py", line 426, in _process_worker
    call_item = call_queue.get(block=True, timeout=timeout)
  File "/usr/local/usrapps/ddomlab/sdehgha2/pls-dataset-env/lib/python3.10/multiprocessing/queues.py", line 108, in get
    if not self._rlock.acquire(block, timeout):
KeyboardInterrupt

During handling of the above exception, another exception occurred:

Traceback (most recent call last):
  File "/usr/local/usrapps/ddomlab/sdehgha2/pls-dataset-env/lib/python3.10/multiprocessing/process.py", line 314, in _bootstrap
    self.run()
  File "/usr/local/usrapps/ddomlab/sdehgha2/pls-dataset-env/lib/python3.10/multiprocessing/process.py", line 108, in run
    self._target(*self._args, **self._kwargs)
  File "/usr/local/usrapps/ddomlab/sdehgha2/pls-dataset-env/lib/python3.10/site-packages/joblib/externals/loky/process_executor.py", line 438, in _process_worker
    previous_tb = traceback.format_exc()
  File "/usr/local/usrapps/ddomlab/sdehgha2/pls-dataset-env/lib/python3.10/traceback.py", line 183, in format_exc
    return "".join(format_exception(*sys.exc_info(), limit=limit, chain=chain))
  File "/usr/local/usrapps/ddomlab/sdehgha2/pls-dataset-env/lib/python3.10/traceback.py", line 135, in format_exception
    te = TracebackException(type(value), value, tb, limit=limit, compact=True)
  File "/usr/local/usrapps/ddomlab/sdehgha2/pls-dataset-env/lib/python3.10/traceback.py", line 489, in __init__
    def __init__(self, exc_type, exc_value, exc_traceback, *, limit=None,
KeyboardInterrupt
Traceback (most recent call last):
  File "/usr/local/usrapps/ddomlab/sdehgha2/pls-dataset-env/lib/python3.10/site-packages/joblib/externals/loky/process_executor.py", line 426, in _process_worker
    call_item = call_queue.get(block=True, timeout=timeout)
  File "/usr/local/usrapps/ddomlab/sdehgha2/pls-dataset-env/lib/python3.10/multiprocessing/queues.py", line 108, in get
    if not self._rlock.acquire(block, timeout):
KeyboardInterrupt

During handling of the above exception, another exception occurred:

Traceback (most recent call last):
  File "/usr/local/usrapps/ddomlab/sdehgha2/pls-dataset-env/lib/python3.10/multiprocessing/process.py", line 314, in _bootstrap
    self.run()
  File "/usr/local/usrapps/ddomlab/sdehgha2/pls-dataset-env/lib/python3.10/multiprocessing/process.py", line 108, in run
    self._target(*self._args, **self._kwargs)
  File "/usr/local/usrapps/ddomlab/sdehgha2/pls-dataset-env/lib/python3.10/site-packages/joblib/externals/loky/process_executor.py", line 438, in _process_worker
    previous_tb = traceback.format_exc()
  File "/usr/local/usrapps/ddomlab/sdehgha2/pls-dataset-env/lib/python3.10/traceback.py", line 181, in format_exc
    def format_exc(limit=None, chain=True):
KeyboardInterrupt
Traceback (most recent call last):
  File "/usr/local/usrapps/ddomlab/sdehgha2/pls-dataset-env/lib/python3.10/site-packages/joblib/externals/loky/process_executor.py", line 426, in _process_worker
    call_item = call_queue.get(block=True, timeout=timeout)
  File "/usr/local/usrapps/ddomlab/sdehgha2/pls-dataset-env/lib/python3.10/multiprocessing/queues.py", line 108, in get
    if not self._rlock.acquire(block, timeout):
KeyboardInterrupt

During handling of the above exception, another exception occurred:

Traceback (most recent call last):
  File "/usr/local/usrapps/ddomlab/sdehgha2/pls-dataset-env/lib/python3.10/multiprocessing/process.py", line 314, in _bootstrap
    self.run()
  File "/usr/local/usrapps/ddomlab/sdehgha2/pls-dataset-env/lib/python3.10/multiprocessing/process.py", line 108, in run
    self._target(*self._args, **self._kwargs)
  File "/usr/local/usrapps/ddomlab/sdehgha2/pls-dataset-env/lib/python3.10/site-packages/joblib/externals/loky/process_executor.py", line 438, in _process_worker
    previous_tb = traceback.format_exc()
  File "/usr/local/usrapps/ddomlab/sdehgha2/pls-dataset-env/lib/python3.10/traceback.py", line 183, in format_exc
    return "".join(format_exception(*sys.exc_info(), limit=limit, chain=chain))
  File "/usr/local/usrapps/ddomlab/sdehgha2/pls-dataset-env/lib/python3.10/traceback.py", line 135, in format_exception
    te = TracebackException(type(value), value, tb, limit=limit, compact=True)
  File "/usr/local/usrapps/ddomlab/sdehgha2/pls-dataset-env/lib/python3.10/traceback.py", line 499, in __init__
    _seen.add(id(exc_value))
KeyboardInterrupt
Traceback (most recent call last):
  File "/usr/local/usrapps/ddomlab/sdehgha2/pls-dataset-env/lib/python3.10/site-packages/joblib/externals/loky/process_executor.py", line 426, in _process_worker
    call_item = call_queue.get(block=True, timeout=timeout)
  File "/usr/local/usrapps/ddomlab/sdehgha2/pls-dataset-env/lib/python3.10/multiprocessing/queues.py", line 108, in get
    if not self._rlock.acquire(block, timeout):
KeyboardInterrupt

During handling of the above exception, another exception occurred:

Traceback (most recent call last):
  File "/usr/local/usrapps/ddomlab/sdehgha2/pls-dataset-env/lib/python3.10/multiprocessing/process.py", line 314, in _bootstrap
    self.run()
  File "/usr/local/usrapps/ddomlab/sdehgha2/pls-dataset-env/lib/python3.10/multiprocessing/process.py", line 108, in run
    self._target(*self._args, **self._kwargs)
  File "/usr/local/usrapps/ddomlab/sdehgha2/pls-dataset-env/lib/python3.10/site-packages/joblib/externals/loky/process_executor.py", line 438, in _process_worker
    previous_tb = traceback.format_exc()
  File "/usr/local/usrapps/ddomlab/sdehgha2/pls-dataset-env/lib/python3.10/traceback.py", line 183, in format_exc
    return "".join(format_exception(*sys.exc_info(), limit=limit, chain=chain))
  File "/usr/local/usrapps/ddomlab/sdehgha2/pls-dataset-env/lib/python3.10/traceback.py", line 135, in format_exception
    te = TracebackException(type(value), value, tb, limit=limit, compact=True)
  File "/usr/local/usrapps/ddomlab/sdehgha2/pls-dataset-env/lib/python3.10/traceback.py", line 498, in __init__
    _seen = set()
KeyboardInterrupt
Traceback (most recent call last):
  File "/usr/local/usrapps/ddomlab/sdehgha2/pls-dataset-env/lib/python3.10/site-packages/joblib/externals/loky/process_executor.py", line 426, in _process_worker
    call_item = call_queue.get(block=True, timeout=timeout)
  File "/usr/local/usrapps/ddomlab/sdehgha2/pls-dataset-env/lib/python3.10/multiprocessing/queues.py", line 108, in get
    if not self._rlock.acquire(block, timeout):
KeyboardInterrupt

During handling of the above exception, another exception occurred:

Traceback (most recent call last):
  File "/usr/local/usrapps/ddomlab/sdehgha2/pls-dataset-env/lib/python3.10/multiprocessing/process.py", line 314, in _bootstrap
    self.run()
  File "/usr/local/usrapps/ddomlab/sdehgha2/pls-dataset-env/lib/python3.10/multiprocessing/process.py", line 108, in run
    self._target(*self._args, **self._kwargs)
  File "/usr/local/usrapps/ddomlab/sdehgha2/pls-dataset-env/lib/python3.10/site-packages/joblib/externals/loky/process_executor.py", line 438, in _process_worker
    previous_tb = traceback.format_exc()
  File "/usr/local/usrapps/ddomlab/sdehgha2/pls-dataset-env/lib/python3.10/traceback.py", line 183, in format_exc
    return "".join(format_exception(*sys.exc_info(), limit=limit, chain=chain))
  File "/usr/local/usrapps/ddomlab/sdehgha2/pls-dataset-env/lib/python3.10/traceback.py", line 135, in format_exception
    te = TracebackException(type(value), value, tb, limit=limit, compact=True)
  File "/usr/local/usrapps/ddomlab/sdehgha2/pls-dataset-env/lib/python3.10/traceback.py", line 502, in __init__
    self.stack = StackSummary.extract(
  File "/usr/local/usrapps/ddomlab/sdehgha2/pls-dataset-env/lib/python3.10/traceback.py", line 364, in extract
    for f, lineno in frame_gen:
  File "/usr/local/usrapps/ddomlab/sdehgha2/pls-dataset-env/lib/python3.10/traceback.py", line 328, in walk_tb
    while tb is not None:
KeyboardInterrupt
Traceback (most recent call last):
  File "/usr/local/usrapps/ddomlab/sdehgha2/pls-dataset-env/lib/python3.10/site-packages/joblib/externals/loky/process_executor.py", line 426, in _process_worker
    call_item = call_queue.get(block=True, timeout=timeout)
  File "/usr/local/usrapps/ddomlab/sdehgha2/pls-dataset-env/lib/python3.10/multiprocessing/queues.py", line 108, in get
    if not self._rlock.acquire(block, timeout):
KeyboardInterrupt

During handling of the above exception, another exception occurred:

Traceback (most recent call last):
  File "/usr/local/usrapps/ddomlab/sdehgha2/pls-dataset-env/lib/python3.10/multiprocessing/process.py", line 314, in _bootstrap
    self.run()
  File "/usr/local/usrapps/ddomlab/sdehgha2/pls-dataset-env/lib/python3.10/multiprocessing/process.py", line 108, in run
    self._target(*self._args, **self._kwargs)
  File "/usr/local/usrapps/ddomlab/sdehgha2/pls-dataset-env/lib/python3.10/site-packages/joblib/externals/loky/process_executor.py", line 438, in _process_worker
    previous_tb = traceback.format_exc()
  File "/usr/local/usrapps/ddomlab/sdehgha2/pls-dataset-env/lib/python3.10/traceback.py", line 183, in format_exc
    return "".join(format_exception(*sys.exc_info(), limit=limit, chain=chain))
  File "/usr/local/usrapps/ddomlab/sdehgha2/pls-dataset-env/lib/python3.10/traceback.py", line 135, in format_exception
    te = TracebackException(type(value), value, tb, limit=limit, compact=True)
  File "/usr/local/usrapps/ddomlab/sdehgha2/pls-dataset-env/lib/python3.10/traceback.py", line 502, in __init__
    self.stack = StackSummary.extract(
  File "/usr/local/usrapps/ddomlab/sdehgha2/pls-dataset-env/lib/python3.10/traceback.py", line 370, in extract
    linecache.lazycache(filename, f.f_globals)
  File "/usr/local/usrapps/ddomlab/sdehgha2/pls-dataset-env/lib/python3.10/linecache.py", line 147, in lazycache
    def lazycache(filename, module_globals):
KeyboardInterrupt
    self._run_search(evaluate_candidates)
  File "/usr/local/usrapps/ddomlab/sdehgha2/pls-dataset-env/lib/python3.10/site-packages/skopt/searchcv.py", line 599, in _run_search
    optim_result, score_name = self._step(
  File "/usr/local/usrapps/ddomlab/sdehgha2/pls-dataset-env/lib/python3.10/site-packages/skopt/searchcv.py", line 445, in _step
    params = optimizer.ask(n_points=n_points)
  File "/usr/local/usrapps/ddomlab/sdehgha2/pls-dataset-env/lib/python3.10/site-packages/skopt/optimizer/optimizer.py", line 464, in ask
    opt._tell(x, y_lie)
  File "/usr/local/usrapps/ddomlab/sdehgha2/pls-dataset-env/lib/python3.10/site-packages/skopt/optimizer/optimizer.py", line 657, in _tell
    results = Parallel(n_jobs=self.n_jobs)(
  File "/usr/local/usrapps/ddomlab/sdehgha2/pls-dataset-env/lib/python3.10/site-packages/joblib/parallel.py", line 1918, in __call__
    return output if self.return_generator else list(output)
  File "/usr/local/usrapps/ddomlab/sdehgha2/pls-dataset-env/lib/python3.10/site-packages/joblib/parallel.py", line 1847, in _get_sequential_output
    res = func(*args, **kwargs)
  File "/usr/local/usrapps/ddomlab/sdehgha2/pls-dataset-env/lib/python3.10/site-packages/scipy/optimize/_lbfgsb_py.py", line 237, in fmin_l_bfgs_b
    res = _minimize_lbfgsb(fun, x0, args=args, jac=jac, bounds=bounds,
  File "/usr/local/usrapps/ddomlab/sdehgha2/pls-dataset-env/lib/python3.10/site-packages/scipy/optimize/_lbfgsb_py.py", line 407, in _minimize_lbfgsb
    f, g = func_and_grad(x)
  File "/usr/local/usrapps/ddomlab/sdehgha2/pls-dataset-env/lib/python3.10/site-packages/scipy/optimize/_differentiable_functions.py", line 343, in fun_and_grad
    self._update_fun()
  File "/usr/local/usrapps/ddomlab/sdehgha2/pls-dataset-env/lib/python3.10/site-packages/scipy/optimize/_differentiable_functions.py", line 294, in _update_fun
    fx = self._wrapped_fun(self.x)
  File "/usr/local/usrapps/ddomlab/sdehgha2/pls-dataset-env/lib/python3.10/site-packages/scipy/optimize/_differentiable_functions.py", line 20, in wrapped
    fx = fun(np.copy(x), *args)
  File "/usr/local/usrapps/ddomlab/sdehgha2/pls-dataset-env/lib/python3.10/site-packages/scipy/optimize/_optimize.py", line 79, in __call__
    self._compute_if_needed(x, *args)
  File "/usr/local/usrapps/ddomlab/sdehgha2/pls-dataset-env/lib/python3.10/site-packages/scipy/optimize/_optimize.py", line 73, in _compute_if_needed
    fg = self.fun(x, *args)
  File "/usr/local/usrapps/ddomlab/sdehgha2/pls-dataset-env/lib/python3.10/site-packages/skopt/acquisition.py", line 16, in gaussian_acquisition_1D
    return _gaussian_acquisition(
  File "/usr/local/usrapps/ddomlab/sdehgha2/pls-dataset-env/lib/python3.10/site-packages/skopt/acquisition.py", line 59, in _gaussian_acquisition
    func_and_grad = gaussian_ei(X, model, y_opt, xi, return_grad)
  File "/usr/local/usrapps/ddomlab/sdehgha2/pls-dataset-env/lib/python3.10/site-packages/skopt/acquisition.py", line 294, in gaussian_ei
    mu, std, mu_grad, std_grad = model.predict(
  File "/usr/local/usrapps/ddomlab/sdehgha2/pls-dataset-env/lib/python3.10/site-packages/skopt/learning/gaussian_process/gpr.py", line 316, in predict
    X = check_array(X)
  File "/usr/local/usrapps/ddomlab/sdehgha2/pls-dataset-env/lib/python3.10/site-packages/sklearn/utils/validation.py", line 840, in check_array
    if isinstance(array, np.matrix):
KeyboardInterrupt

During handling of the above exception, another exception occurred:

Traceback (most recent call last):
  File "/gpfs_common/share03/ddomlab/sdehgha2/working-space/main/P1_pls-dataset/pls-dataset-space/PLS-Dataset/code_/training/hpc_submit_training_Rh/../train_numerical_only.py", line 162, in <module>
    main_numerical_only(
  File "/gpfs_common/share03/ddomlab/sdehgha2/working-space/main/P1_pls-dataset/pls-dataset-space/PLS-Dataset/code_/training/hpc_submit_training_Rh/../train_numerical_only.py", line 36, in main_numerical_only
    scores, predictions,data_shapes  = train_regressor(
  File "/gpfs_common/share03/ddomlab/sdehgha2/working-space/main/P1_pls-dataset/pls-dataset-space/PLS-Dataset/code_/training/training_utils.py", line 65, in train_regressor
    scores, predictions, data_shape = _prepare_data(
  File "/gpfs_common/share03/ddomlab/sdehgha2/working-space/main/P1_pls-dataset/pls-dataset-space/PLS-Dataset/code_/training/training_utils.py", line 136, in _prepare_data
    score,predication= run(
  File "/gpfs_common/share03/ddomlab/sdehgha2/working-space/main/P1_pls-dataset/pls-dataset-space/PLS-Dataset/code_/training/training_utils.py", line 182, in run
    best_estimator, regressor_params = _optimize_hyperparams(
  File "/gpfs_common/share03/ddomlab/sdehgha2/working-space/main/P1_pls-dataset/pls-dataset-space/PLS-Dataset/code_/training/training_utils.py", line 249, in _optimize_hyperparams
    bayes.fit(X_train, y_train)
  File "/usr/local/usrapps/ddomlab/sdehgha2/pls-dataset-env/lib/python3.10/site-packages/skopt/searchcv.py", line 542, in fit
    super().fit(X=X, y=y, groups=groups, **fit_params)
  File "/usr/local/usrapps/ddomlab/sdehgha2/pls-dataset-env/lib/python3.10/site-packages/sklearn/base.py", line 1473, in wrapper
    return fit_method(estimator, *args, **kwargs)
  File "/usr/local/usrapps/ddomlab/sdehgha2/pls-dataset-env/lib/python3.10/site-packages/sklearn/model_selection/_search.py", line 947, in fit
    with parallel:
  File "/usr/local/usrapps/ddomlab/sdehgha2/pls-dataset-env/lib/python3.10/site-packages/joblib/parallel.py", line 1354, in __exit__
    self._terminate_and_reset()
  File "/usr/local/usrapps/ddomlab/sdehgha2/pls-dataset-env/lib/python3.10/site-packages/joblib/parallel.py", line 1386, in _terminate_and_reset
    self._backend.terminate()
  File "/usr/local/usrapps/ddomlab/sdehgha2/pls-dataset-env/lib/python3.10/site-packages/joblib/_parallel_backends.py", line 610, in terminate
    self._workers._temp_folder_manager._clean_temporary_resources(
  File "/usr/local/usrapps/ddomlab/sdehgha2/pls-dataset-env/lib/python3.10/site-packages/joblib/_memmapping_reducer.py", line 641, in _clean_temporary_resources
    delete_folder(
  File "/usr/local/usrapps/ddomlab/sdehgha2/pls-dataset-env/lib/python3.10/site-packages/joblib/disk.py", line 121, in delete_folder
    util.debug(
  File "/usr/local/usrapps/ddomlab/sdehgha2/pls-dataset-env/lib/python3.10/multiprocessing/util.py", line 48, in debug
    def debug(msg, *args):
KeyboardInterrupt
