Process LokyProcess-10:
Process LokyProcess-14:
Process LokyProcess-5:
Process LokyProcess-9:
Process LokyProcess-24:
Process LokyProcess-3:
Process LokyProcess-7:
Process LokyProcess-2:
Process LokyProcess-18:
Process LokyProcess-4:
Process LokyProcess-8:
Process LokyProcess-6:
Traceback (most recent call last):
  File "/usr/local/usrapps/ddomlab/sdehgha2/pls-dataset-env/lib/python3.10/site-packages/joblib/parallel.py", line 1650, in _get_outputs
    yield from self._retrieve()
  File "/usr/local/usrapps/ddomlab/sdehgha2/pls-dataset-env/lib/python3.10/site-packages/joblib/parallel.py", line 1762, in _retrieve
    time.sleep(0.01)
KeyboardInterrupt

During handling of the above exception, another exception occurred:

Traceback (most recent call last):
  File "/gpfs_common/share03/ddomlab/sdehgha2/working-space/main/P1_pls-dataset/pls-dataset-space/PLS-Dataset/code_/training/hpc_submit_training_Rh/../train_numerical_only.py", line 162, in <module>
    main_numerical_only(
  File "/gpfs_common/share03/ddomlab/sdehgha2/working-space/main/P1_pls-dataset/pls-dataset-space/PLS-Dataset/code_/training/hpc_submit_training_Rh/../train_numerical_only.py", line 36, in main_numerical_only
    scores, predictions,data_shapes  = train_regressor(
  File "/gpfs_common/share03/ddomlab/sdehgha2/working-space/main/P1_pls-dataset/pls-dataset-space/PLS-Dataset/code_/training/training_utils.py", line 65, in train_regressor
    scores, predictions, data_shape = _prepare_data(
  File "/gpfs_common/share03/ddomlab/sdehgha2/working-space/main/P1_pls-dataset/pls-dataset-space/PLS-Dataset/code_/training/training_utils.py", line 136, in _prepare_data
    score,predication= run(
  File "/gpfs_common/share03/ddomlab/sdehgha2/working-space/main/P1_pls-dataset/pls-dataset-space/PLS-Dataset/code_/training/training_utils.py", line 182, in run
    best_estimator, regressor_params = _optimize_hyperparams(
  File "/gpfs_common/share03/ddomlab/sdehgha2/working-space/main/P1_pls-dataset/pls-dataset-space/PLS-Dataset/code_/training/training_utils.py", line 249, in _optimize_hyperparams
    bayes.fit(X_train, y_train)
  File "/usr/local/usrapps/ddomlab/sdehgha2/pls-dataset-env/lib/python3.10/site-packages/skopt/searchcv.py", line 542, in fit
    super().fit(X=X, y=y, groups=groups, **fit_params)
  File "/usr/local/usrapps/ddomlab/sdehgha2/pls-dataset-env/lib/python3.10/site-packages/sklearn/base.py", line 1473, in wrapper
Process LokyProcess-11:
Traceback (most recent call last):
Traceback (most recent call last):
  File "/usr/local/usrapps/ddomlab/sdehgha2/pls-dataset-env/lib/python3.10/site-packages/joblib/externals/loky/process_executor.py", line 426, in _process_worker
    call_item = call_queue.get(block=True, timeout=timeout)
  File "/usr/local/usrapps/ddomlab/sdehgha2/pls-dataset-env/lib/python3.10/multiprocessing/queues.py", line 108, in get
    if not self._rlock.acquire(block, timeout):
  File "/usr/local/usrapps/ddomlab/sdehgha2/pls-dataset-env/lib/python3.10/site-packages/joblib/externals/loky/process_executor.py", line 426, in _process_worker
    call_item = call_queue.get(block=True, timeout=timeout)
KeyboardInterrupt
  File "/usr/local/usrapps/ddomlab/sdehgha2/pls-dataset-env/lib/python3.10/multiprocessing/queues.py", line 108, in get
    if not self._rlock.acquire(block, timeout):

During handling of the above exception, another exception occurred:

KeyboardInterrupt
Traceback (most recent call last):

During handling of the above exception, another exception occurred:

Traceback (most recent call last):
  File "/usr/local/usrapps/ddomlab/sdehgha2/pls-dataset-env/lib/python3.10/multiprocessing/process.py", line 314, in _bootstrap
    self.run()
  File "/usr/local/usrapps/ddomlab/sdehgha2/pls-dataset-env/lib/python3.10/multiprocessing/process.py", line 314, in _bootstrap
    self.run()
  File "/usr/local/usrapps/ddomlab/sdehgha2/pls-dataset-env/lib/python3.10/multiprocessing/process.py", line 108, in run
    self._target(*self._args, **self._kwargs)
  File "/usr/local/usrapps/ddomlab/sdehgha2/pls-dataset-env/lib/python3.10/multiprocessing/process.py", line 108, in run
    self._target(*self._args, **self._kwargs)
  File "/usr/local/usrapps/ddomlab/sdehgha2/pls-dataset-env/lib/python3.10/site-packages/joblib/externals/loky/process_executor.py", line 438, in _process_worker
    previous_tb = traceback.format_exc()
  File "/usr/local/usrapps/ddomlab/sdehgha2/pls-dataset-env/lib/python3.10/traceback.py", line 183, in format_exc
    return "".join(format_exception(*sys.exc_info(), limit=limit, chain=chain))
  File "/usr/local/usrapps/ddomlab/sdehgha2/pls-dataset-env/lib/python3.10/traceback.py", line 135, in format_exception
    te = TracebackException(type(value), value, tb, limit=limit, compact=True)
  File "/usr/local/usrapps/ddomlab/sdehgha2/pls-dataset-env/lib/python3.10/traceback.py", line 502, in __init__
    self.stack = StackSummary.extract(
  File "/usr/local/usrapps/ddomlab/sdehgha2/pls-dataset-env/lib/python3.10/traceback.py", line 353, in extract
    limit = getattr(sys, 'tracebacklimit', None)
KeyboardInterrupt
  File "/usr/local/usrapps/ddomlab/sdehgha2/pls-dataset-env/lib/python3.10/site-packages/joblib/externals/loky/process_executor.py", line 438, in _process_worker
    previous_tb = traceback.format_exc()
  File "/usr/local/usrapps/ddomlab/sdehgha2/pls-dataset-env/lib/python3.10/traceback.py", line 183, in format_exc
    return "".join(format_exception(*sys.exc_info(), limit=limit, chain=chain))
  File "/usr/local/usrapps/ddomlab/sdehgha2/pls-dataset-env/lib/python3.10/traceback.py", line 124, in format_exception
    def format_exception(exc, /, value=_sentinel, tb=_sentinel, limit=None, \
KeyboardInterrupt
Traceback (most recent call last):
  File "/usr/local/usrapps/ddomlab/sdehgha2/pls-dataset-env/lib/python3.10/site-packages/joblib/externals/loky/process_executor.py", line 426, in _process_worker
    call_item = call_queue.get(block=True, timeout=timeout)
  File "/usr/local/usrapps/ddomlab/sdehgha2/pls-dataset-env/lib/python3.10/multiprocessing/queues.py", line 108, in get
    if not self._rlock.acquire(block, timeout):
KeyboardInterrupt

During handling of the above exception, another exception occurred:

Traceback (most recent call last):
  File "/usr/local/usrapps/ddomlab/sdehgha2/pls-dataset-env/lib/python3.10/multiprocessing/process.py", line 314, in _bootstrap
    self.run()
  File "/usr/local/usrapps/ddomlab/sdehgha2/pls-dataset-env/lib/python3.10/multiprocessing/process.py", line 108, in run
    self._target(*self._args, **self._kwargs)
  File "/usr/local/usrapps/ddomlab/sdehgha2/pls-dataset-env/lib/python3.10/site-packages/joblib/externals/loky/process_executor.py", line 426, in _process_worker
    call_item = call_queue.get(block=True, timeout=timeout)
KeyboardInterrupt
Traceback (most recent call last):
  File "/usr/local/usrapps/ddomlab/sdehgha2/pls-dataset-env/lib/python3.10/site-packages/joblib/externals/loky/process_executor.py", line 426, in _process_worker
    call_item = call_queue.get(block=True, timeout=timeout)
  File "/usr/local/usrapps/ddomlab/sdehgha2/pls-dataset-env/lib/python3.10/multiprocessing/queues.py", line 108, in get
    if not self._rlock.acquire(block, timeout):
KeyboardInterrupt

During handling of the above exception, another exception occurred:

Traceback (most recent call last):
  File "/usr/local/usrapps/ddomlab/sdehgha2/pls-dataset-env/lib/python3.10/multiprocessing/process.py", line 314, in _bootstrap
    self.run()
  File "/usr/local/usrapps/ddomlab/sdehgha2/pls-dataset-env/lib/python3.10/multiprocessing/process.py", line 108, in run
    self._target(*self._args, **self._kwargs)
  File "/usr/local/usrapps/ddomlab/sdehgha2/pls-dataset-env/lib/python3.10/site-packages/joblib/externals/loky/process_executor.py", line 438, in _process_worker
    previous_tb = traceback.format_exc()
  File "/usr/local/usrapps/ddomlab/sdehgha2/pls-dataset-env/lib/python3.10/traceback.py", line 183, in format_exc
    return "".join(format_exception(*sys.exc_info(), limit=limit, chain=chain))
  File "/usr/local/usrapps/ddomlab/sdehgha2/pls-dataset-env/lib/python3.10/traceback.py", line 135, in format_exception
    te = TracebackException(type(value), value, tb, limit=limit, compact=True)
  File "/usr/local/usrapps/ddomlab/sdehgha2/pls-dataset-env/lib/python3.10/traceback.py", line 502, in __init__
    self.stack = StackSummary.extract(
  File "/usr/local/usrapps/ddomlab/sdehgha2/pls-dataset-env/lib/python3.10/traceback.py", line 379, in extract
    linecache.checkcache(filename)
  File "/usr/local/usrapps/ddomlab/sdehgha2/pls-dataset-env/lib/python3.10/linecache.py", line 72, in checkcache
    stat = os.stat(fullname)
KeyboardInterrupt
    return fit_method(estimator, *args, **kwargs)
  File "/usr/local/usrapps/ddomlab/sdehgha2/pls-dataset-env/lib/python3.10/site-packages/sklearn/model_selection/_search.py", line 1019, in fit
Traceback (most recent call last):
Traceback (most recent call last):
  File "/usr/local/usrapps/ddomlab/sdehgha2/pls-dataset-env/lib/python3.10/site-packages/joblib/externals/loky/process_executor.py", line 426, in _process_worker
    call_item = call_queue.get(block=True, timeout=timeout)
  File "/usr/local/usrapps/ddomlab/sdehgha2/pls-dataset-env/lib/python3.10/site-packages/joblib/externals/loky/process_executor.py", line 426, in _process_worker
    call_item = call_queue.get(block=True, timeout=timeout)
  File "/usr/local/usrapps/ddomlab/sdehgha2/pls-dataset-env/lib/python3.10/multiprocessing/queues.py", line 108, in get
    if not self._rlock.acquire(block, timeout):
  File "/usr/local/usrapps/ddomlab/sdehgha2/pls-dataset-env/lib/python3.10/multiprocessing/queues.py", line 108, in get
    if not self._rlock.acquire(block, timeout):
KeyboardInterrupt
KeyboardInterrupt

During handling of the above exception, another exception occurred:


During handling of the above exception, another exception occurred:

Traceback (most recent call last):
Traceback (most recent call last):
  File "/usr/local/usrapps/ddomlab/sdehgha2/pls-dataset-env/lib/python3.10/multiprocessing/process.py", line 314, in _bootstrap
    self.run()
  File "/usr/local/usrapps/ddomlab/sdehgha2/pls-dataset-env/lib/python3.10/multiprocessing/process.py", line 108, in run
    self._target(*self._args, **self._kwargs)
  File "/usr/local/usrapps/ddomlab/sdehgha2/pls-dataset-env/lib/python3.10/site-packages/joblib/externals/loky/process_executor.py", line 438, in _process_worker
    previous_tb = traceback.format_exc()
  File "/usr/local/usrapps/ddomlab/sdehgha2/pls-dataset-env/lib/python3.10/traceback.py", line 183, in format_exc
    return "".join(format_exception(*sys.exc_info(), limit=limit, chain=chain))
  File "/usr/local/usrapps/ddomlab/sdehgha2/pls-dataset-env/lib/python3.10/traceback.py", line 135, in format_exception
    te = TracebackException(type(value), value, tb, limit=limit, compact=True)
  File "/usr/local/usrapps/ddomlab/sdehgha2/pls-dataset-env/lib/python3.10/traceback.py", line 489, in __init__
    def __init__(self, exc_type, exc_value, exc_traceback, *, limit=None,
KeyboardInterrupt
  File "/usr/local/usrapps/ddomlab/sdehgha2/pls-dataset-env/lib/python3.10/multiprocessing/process.py", line 314, in _bootstrap
    self.run()
  File "/usr/local/usrapps/ddomlab/sdehgha2/pls-dataset-env/lib/python3.10/multiprocessing/process.py", line 108, in run
    self._target(*self._args, **self._kwargs)
  File "/usr/local/usrapps/ddomlab/sdehgha2/pls-dataset-env/lib/python3.10/site-packages/joblib/externals/loky/process_executor.py", line 438, in _process_worker
    previous_tb = traceback.format_exc()
  File "/usr/local/usrapps/ddomlab/sdehgha2/pls-dataset-env/lib/python3.10/traceback.py", line 183, in format_exc
    return "".join(format_exception(*sys.exc_info(), limit=limit, chain=chain))
  File "/usr/local/usrapps/ddomlab/sdehgha2/pls-dataset-env/lib/python3.10/traceback.py", line 135, in format_exception
    te = TracebackException(type(value), value, tb, limit=limit, compact=True)
  File "/usr/local/usrapps/ddomlab/sdehgha2/pls-dataset-env/lib/python3.10/traceback.py", line 502, in __init__
    self.stack = StackSummary.extract(
  File "/usr/local/usrapps/ddomlab/sdehgha2/pls-dataset-env/lib/python3.10/traceback.py", line 353, in extract
    limit = getattr(sys, 'tracebacklimit', None)
KeyboardInterrupt
Traceback (most recent call last):
  File "/usr/local/usrapps/ddomlab/sdehgha2/pls-dataset-env/lib/python3.10/site-packages/joblib/externals/loky/process_executor.py", line 426, in _process_worker
    call_item = call_queue.get(block=True, timeout=timeout)
  File "/usr/local/usrapps/ddomlab/sdehgha2/pls-dataset-env/lib/python3.10/multiprocessing/queues.py", line 108, in get
    if not self._rlock.acquire(block, timeout):
KeyboardInterrupt

During handling of the above exception, another exception occurred:

Traceback (most recent call last):
  File "/usr/local/usrapps/ddomlab/sdehgha2/pls-dataset-env/lib/python3.10/multiprocessing/process.py", line 314, in _bootstrap
    self.run()
  File "/usr/local/usrapps/ddomlab/sdehgha2/pls-dataset-env/lib/python3.10/multiprocessing/process.py", line 108, in run
    self._target(*self._args, **self._kwargs)
  File "/usr/local/usrapps/ddomlab/sdehgha2/pls-dataset-env/lib/python3.10/site-packages/joblib/externals/loky/process_executor.py", line 438, in _process_worker
    previous_tb = traceback.format_exc()
Traceback (most recent call last):
  File "/usr/local/usrapps/ddomlab/sdehgha2/pls-dataset-env/lib/python3.10/traceback.py", line 183, in format_exc
    return "".join(format_exception(*sys.exc_info(), limit=limit, chain=chain))
  File "/usr/local/usrapps/ddomlab/sdehgha2/pls-dataset-env/lib/python3.10/traceback.py", line 135, in format_exception
    te = TracebackException(type(value), value, tb, limit=limit, compact=True)
  File "/usr/local/usrapps/ddomlab/sdehgha2/pls-dataset-env/lib/python3.10/traceback.py", line 502, in __init__
    self.stack = StackSummary.extract(
  File "/usr/local/usrapps/ddomlab/sdehgha2/pls-dataset-env/lib/python3.10/traceback.py", line 376, in extract
    result.append(FrameSummary(
  File "/usr/local/usrapps/ddomlab/sdehgha2/pls-dataset-env/lib/python3.10/site-packages/joblib/externals/loky/process_executor.py", line 426, in _process_worker
    call_item = call_queue.get(block=True, timeout=timeout)
  File "/usr/local/usrapps/ddomlab/sdehgha2/pls-dataset-env/lib/python3.10/traceback.py", line 259, in __init__
    def __init__(self, filename, lineno, name, *, lookup_line=True,
  File "/usr/local/usrapps/ddomlab/sdehgha2/pls-dataset-env/lib/python3.10/multiprocessing/queues.py", line 108, in get
    if not self._rlock.acquire(block, timeout):
KeyboardInterrupt
KeyboardInterrupt

During handling of the above exception, another exception occurred:

Traceback (most recent call last):
  File "/usr/local/usrapps/ddomlab/sdehgha2/pls-dataset-env/lib/python3.10/multiprocessing/process.py", line 314, in _bootstrap
    self.run()
  File "/usr/local/usrapps/ddomlab/sdehgha2/pls-dataset-env/lib/python3.10/multiprocessing/process.py", line 108, in run
    self._target(*self._args, **self._kwargs)
  File "/usr/local/usrapps/ddomlab/sdehgha2/pls-dataset-env/lib/python3.10/site-packages/joblib/externals/loky/process_executor.py", line 438, in _process_worker
    previous_tb = traceback.format_exc()
  File "/usr/local/usrapps/ddomlab/sdehgha2/pls-dataset-env/lib/python3.10/traceback.py", line 183, in format_exc
    return "".join(format_exception(*sys.exc_info(), limit=limit, chain=chain))
  File "/usr/local/usrapps/ddomlab/sdehgha2/pls-dataset-env/lib/python3.10/traceback.py", line 135, in format_exception
    te = TracebackException(type(value), value, tb, limit=limit, compact=True)
  File "/usr/local/usrapps/ddomlab/sdehgha2/pls-dataset-env/lib/python3.10/traceback.py", line 489, in __init__
    def __init__(self, exc_type, exc_value, exc_traceback, *, limit=None,
KeyboardInterrupt
Traceback (most recent call last):
  File "/usr/local/usrapps/ddomlab/sdehgha2/pls-dataset-env/lib/python3.10/site-packages/joblib/externals/loky/process_executor.py", line 426, in _process_worker
    call_item = call_queue.get(block=True, timeout=timeout)
  File "/usr/local/usrapps/ddomlab/sdehgha2/pls-dataset-env/lib/python3.10/multiprocessing/queues.py", line 108, in get
    if not self._rlock.acquire(block, timeout):
KeyboardInterrupt

During handling of the above exception, another exception occurred:

Traceback (most recent call last):
  File "/usr/local/usrapps/ddomlab/sdehgha2/pls-dataset-env/lib/python3.10/multiprocessing/process.py", line 314, in _bootstrap
    self.run()
  File "/usr/local/usrapps/ddomlab/sdehgha2/pls-dataset-env/lib/python3.10/multiprocessing/process.py", line 108, in run
    self._target(*self._args, **self._kwargs)
  File "/usr/local/usrapps/ddomlab/sdehgha2/pls-dataset-env/lib/python3.10/site-packages/joblib/externals/loky/process_executor.py", line 438, in _process_worker
    previous_tb = traceback.format_exc()
  File "/usr/local/usrapps/ddomlab/sdehgha2/pls-dataset-env/lib/python3.10/traceback.py", line 181, in format_exc
    def format_exc(limit=None, chain=True):
KeyboardInterrupt
    self._run_search(evaluate_candidates)
  File "/usr/local/usrapps/ddomlab/sdehgha2/pls-dataset-env/lib/python3.10/site-packages/skopt/searchcv.py", line 599, in _run_search
    optim_result, score_name = self._step(
  File "/usr/local/usrapps/ddomlab/sdehgha2/pls-dataset-env/lib/python3.10/site-packages/skopt/searchcv.py", line 453, in _step
    all_results = evaluate_candidates(params_dict)
  File "/usr/local/usrapps/ddomlab/sdehgha2/pls-dataset-env/lib/python3.10/site-packages/sklearn/model_selection/_search.py", line 965, in evaluate_candidates
    out = parallel(
  File "/usr/local/usrapps/ddomlab/sdehgha2/pls-dataset-env/lib/python3.10/site-packages/sklearn/utils/parallel.py", line 74, in __call__
    return super().__call__(iterable_with_config)
  File "/usr/local/usrapps/ddomlab/sdehgha2/pls-dataset-env/lib/python3.10/site-packages/joblib/parallel.py", line 2007, in __call__
    return output if self.return_generator else list(output)
  File "/usr/local/usrapps/ddomlab/sdehgha2/pls-dataset-env/lib/python3.10/site-packages/joblib/parallel.py", line 1703, in _get_outputs
    self._abort()
  File "/usr/local/usrapps/ddomlab/sdehgha2/pls-dataset-env/lib/python3.10/site-packages/joblib/parallel.py", line 1614, in _abort
    backend.abort_everything(ensure_ready=ensure_ready)
  File "/usr/local/usrapps/ddomlab/sdehgha2/pls-dataset-env/lib/python3.10/site-packages/joblib/_parallel_backends.py", line 620, in abort_everything
    self._workers.terminate(kill_workers=True)
  File "/usr/local/usrapps/ddomlab/sdehgha2/pls-dataset-env/lib/python3.10/site-packages/joblib/executor.py", line 75, in terminate
    self.shutdown(kill_workers=kill_workers)
  File "/usr/local/usrapps/ddomlab/sdehgha2/pls-dataset-env/lib/python3.10/site-packages/joblib/externals/loky/process_executor.py", line 1303, in shutdown
    executor_manager_thread.join()
  File "/usr/local/usrapps/ddomlab/sdehgha2/pls-dataset-env/lib/python3.10/threading.py", line 1096, in join
    self._wait_for_tstate_lock()
  File "/usr/local/usrapps/ddomlab/sdehgha2/pls-dataset-env/lib/python3.10/threading.py", line 1116, in _wait_for_tstate_lock
    if lock.acquire(block, timeout):
KeyboardInterrupt
Traceback (most recent call last):
  File "/usr/local/usrapps/ddomlab/sdehgha2/pls-dataset-env/lib/python3.10/site-packages/joblib/externals/loky/process_executor.py", line 463, in _process_worker
    r = call_item()
  File "/usr/local/usrapps/ddomlab/sdehgha2/pls-dataset-env/lib/python3.10/site-packages/joblib/externals/loky/process_executor.py", line 291, in __call__
    return self.fn(*self.args, **self.kwargs)
  File "/usr/local/usrapps/ddomlab/sdehgha2/pls-dataset-env/lib/python3.10/site-packages/joblib/parallel.py", line 598, in __call__
    return [func(*args, **kwargs)
  File "/usr/local/usrapps/ddomlab/sdehgha2/pls-dataset-env/lib/python3.10/site-packages/joblib/parallel.py", line 598, in <listcomp>
    return [func(*args, **kwargs)
  File "/usr/local/usrapps/ddomlab/sdehgha2/pls-dataset-env/lib/python3.10/site-packages/sklearn/utils/parallel.py", line 136, in __call__
    return self.function(*args, **kwargs)
  File "/usr/local/usrapps/ddomlab/sdehgha2/pls-dataset-env/lib/python3.10/site-packages/sklearn/model_selection/_validation.py", line 888, in _fit_and_score
    estimator.fit(X_train, y_train, **fit_params)
  File "/usr/local/usrapps/ddomlab/sdehgha2/pls-dataset-env/lib/python3.10/site-packages/sklearn/base.py", line 1473, in wrapper
    return fit_method(estimator, *args, **kwargs)
  File "/usr/local/usrapps/ddomlab/sdehgha2/pls-dataset-env/lib/python3.10/site-packages/sklearn/pipeline.py", line 473, in fit
    self._final_estimator.fit(Xt, y, **last_step_params["fit"])
  File "/usr/local/usrapps/ddomlab/sdehgha2/pls-dataset-env/lib/python3.10/site-packages/sklearn/base.py", line 1473, in wrapper
    return fit_method(estimator, *args, **kwargs)
  File "/usr/local/usrapps/ddomlab/sdehgha2/pls-dataset-env/lib/python3.10/site-packages/sklearn/compose/_target.py", line 288, in fit
    self.regressor_.fit(X, y_trans, **fit_params)
  File "/usr/local/usrapps/ddomlab/sdehgha2/pls-dataset-env/lib/python3.10/site-packages/sklearn/base.py", line 1473, in wrapper
    return fit_method(estimator, *args, **kwargs)
  File "/usr/local/usrapps/ddomlab/sdehgha2/pls-dataset-env/lib/python3.10/site-packages/sklearn/ensemble/_forest.py", line 489, in fit
    trees = Parallel(
  File "/usr/local/usrapps/ddomlab/sdehgha2/pls-dataset-env/lib/python3.10/site-packages/sklearn/utils/parallel.py", line 74, in __call__
    return super().__call__(iterable_with_config)
  File "/usr/local/usrapps/ddomlab/sdehgha2/pls-dataset-env/lib/python3.10/site-packages/joblib/parallel.py", line 1918, in __call__
    return output if self.return_generator else list(output)
  File "/usr/local/usrapps/ddomlab/sdehgha2/pls-dataset-env/lib/python3.10/site-packages/joblib/parallel.py", line 1847, in _get_sequential_output
    res = func(*args, **kwargs)
  File "/usr/local/usrapps/ddomlab/sdehgha2/pls-dataset-env/lib/python3.10/site-packages/sklearn/utils/parallel.py", line 135, in __call__
    with config_context(**config):
  File "/usr/local/usrapps/ddomlab/sdehgha2/pls-dataset-env/lib/python3.10/contextlib.py", line 281, in helper
    return _GeneratorContextManager(func, args, kwds)
  File "/usr/local/usrapps/ddomlab/sdehgha2/pls-dataset-env/lib/python3.10/contextlib.py", line 103, in __init__
    self.gen = func(*args, **kwds)
KeyboardInterrupt

During handling of the above exception, another exception occurred:

Traceback (most recent call last):
  File "/usr/local/usrapps/ddomlab/sdehgha2/pls-dataset-env/lib/python3.10/multiprocessing/process.py", line 314, in _bootstrap
    self.run()
  File "/usr/local/usrapps/ddomlab/sdehgha2/pls-dataset-env/lib/python3.10/multiprocessing/process.py", line 108, in run
    self._target(*self._args, **self._kwargs)
  File "/usr/local/usrapps/ddomlab/sdehgha2/pls-dataset-env/lib/python3.10/site-packages/joblib/externals/loky/process_executor.py", line 465, in _process_worker
    exc = _ExceptionWithTraceback(e)
  File "/usr/local/usrapps/ddomlab/sdehgha2/pls-dataset-env/lib/python3.10/site-packages/joblib/externals/loky/process_executor.py", line 247, in __init__
    tb = traceback.format_exception(type(exc), exc, tb)
  File "/usr/local/usrapps/ddomlab/sdehgha2/pls-dataset-env/lib/python3.10/traceback.py", line 135, in format_exception
    te = TracebackException(type(value), value, tb, limit=limit, compact=True)
  File "/usr/local/usrapps/ddomlab/sdehgha2/pls-dataset-env/lib/python3.10/traceback.py", line 502, in __init__
    self.stack = StackSummary.extract(
  File "/usr/local/usrapps/ddomlab/sdehgha2/pls-dataset-env/lib/python3.10/traceback.py", line 370, in extract
    linecache.lazycache(filename, f.f_globals)
  File "/usr/local/usrapps/ddomlab/sdehgha2/pls-dataset-env/lib/python3.10/linecache.py", line 147, in lazycache
    def lazycache(filename, module_globals):
KeyboardInterrupt
Traceback (most recent call last):
  File "/usr/local/usrapps/ddomlab/sdehgha2/pls-dataset-env/lib/python3.10/site-packages/joblib/externals/loky/process_executor.py", line 463, in _process_worker
    r = call_item()
  File "/usr/local/usrapps/ddomlab/sdehgha2/pls-dataset-env/lib/python3.10/site-packages/joblib/externals/loky/process_executor.py", line 291, in __call__
    return self.fn(*self.args, **self.kwargs)
  File "/usr/local/usrapps/ddomlab/sdehgha2/pls-dataset-env/lib/python3.10/site-packages/joblib/parallel.py", line 598, in __call__
    return [func(*args, **kwargs)
  File "/usr/local/usrapps/ddomlab/sdehgha2/pls-dataset-env/lib/python3.10/site-packages/joblib/parallel.py", line 598, in <listcomp>
    return [func(*args, **kwargs)
  File "/usr/local/usrapps/ddomlab/sdehgha2/pls-dataset-env/lib/python3.10/site-packages/sklearn/utils/parallel.py", line 136, in __call__
    return self.function(*args, **kwargs)
  File "/usr/local/usrapps/ddomlab/sdehgha2/pls-dataset-env/lib/python3.10/site-packages/sklearn/model_selection/_validation.py", line 888, in _fit_and_score
    estimator.fit(X_train, y_train, **fit_params)
  File "/usr/local/usrapps/ddomlab/sdehgha2/pls-dataset-env/lib/python3.10/site-packages/sklearn/base.py", line 1473, in wrapper
    return fit_method(estimator, *args, **kwargs)
  File "/usr/local/usrapps/ddomlab/sdehgha2/pls-dataset-env/lib/python3.10/site-packages/sklearn/pipeline.py", line 473, in fit
    self._final_estimator.fit(Xt, y, **last_step_params["fit"])
  File "/usr/local/usrapps/ddomlab/sdehgha2/pls-dataset-env/lib/python3.10/site-packages/sklearn/base.py", line 1473, in wrapper
    return fit_method(estimator, *args, **kwargs)
  File "/usr/local/usrapps/ddomlab/sdehgha2/pls-dataset-env/lib/python3.10/site-packages/sklearn/compose/_target.py", line 288, in fit
    self.regressor_.fit(X, y_trans, **fit_params)
  File "/usr/local/usrapps/ddomlab/sdehgha2/pls-dataset-env/lib/python3.10/site-packages/sklearn/base.py", line 1473, in wrapper
    return fit_method(estimator, *args, **kwargs)
  File "/usr/local/usrapps/ddomlab/sdehgha2/pls-dataset-env/lib/python3.10/site-packages/sklearn/ensemble/_forest.py", line 489, in fit
    trees = Parallel(
  File "/usr/local/usrapps/ddomlab/sdehgha2/pls-dataset-env/lib/python3.10/site-packages/sklearn/utils/parallel.py", line 74, in __call__
    return super().__call__(iterable_with_config)
  File "/usr/local/usrapps/ddomlab/sdehgha2/pls-dataset-env/lib/python3.10/site-packages/joblib/parallel.py", line 1918, in __call__
    return output if self.return_generator else list(output)
  File "/usr/local/usrapps/ddomlab/sdehgha2/pls-dataset-env/lib/python3.10/site-packages/joblib/parallel.py", line 1844, in _get_sequential_output
    for func, args, kwargs in iterable:
  File "/usr/local/usrapps/ddomlab/sdehgha2/pls-dataset-env/lib/python3.10/site-packages/sklearn/utils/parallel.py", line 70, in <genexpr>
    iterable_with_config = (
  File "/usr/local/usrapps/ddomlab/sdehgha2/pls-dataset-env/lib/python3.10/site-packages/sklearn/ensemble/_forest.py", line 494, in <genexpr>
    delayed(_parallel_build_trees)(
  File "/usr/local/usrapps/ddomlab/sdehgha2/pls-dataset-env/lib/python3.10/site-packages/sklearn/utils/parallel.py", line 105, in delayed
    def delayed_function(*args, **kwargs):
  File "/usr/local/usrapps/ddomlab/sdehgha2/pls-dataset-env/lib/python3.10/functools.py", line 58, in update_wrapper
    getattr(wrapper, attr).update(getattr(wrapped, attr, {}))
KeyboardInterrupt

During handling of the above exception, another exception occurred:

Traceback (most recent call last):
  File "/usr/local/usrapps/ddomlab/sdehgha2/pls-dataset-env/lib/python3.10/multiprocessing/process.py", line 314, in _bootstrap
    self.run()
  File "/usr/local/usrapps/ddomlab/sdehgha2/pls-dataset-env/lib/python3.10/multiprocessing/process.py", line 108, in run
    self._target(*self._args, **self._kwargs)
  File "/usr/local/usrapps/ddomlab/sdehgha2/pls-dataset-env/lib/python3.10/site-packages/joblib/externals/loky/process_executor.py", line 465, in _process_worker
    exc = _ExceptionWithTraceback(e)
  File "/usr/local/usrapps/ddomlab/sdehgha2/pls-dataset-env/lib/python3.10/site-packages/joblib/externals/loky/process_executor.py", line 247, in __init__
    tb = traceback.format_exception(type(exc), exc, tb)
  File "/usr/local/usrapps/ddomlab/sdehgha2/pls-dataset-env/lib/python3.10/traceback.py", line 135, in format_exception
    te = TracebackException(type(value), value, tb, limit=limit, compact=True)
  File "/usr/local/usrapps/ddomlab/sdehgha2/pls-dataset-env/lib/python3.10/traceback.py", line 502, in __init__
    self.stack = StackSummary.extract(
  File "/usr/local/usrapps/ddomlab/sdehgha2/pls-dataset-env/lib/python3.10/traceback.py", line 376, in extract
    result.append(FrameSummary(
  File "/usr/local/usrapps/ddomlab/sdehgha2/pls-dataset-env/lib/python3.10/traceback.py", line 274, in __init__
    if lookup_line:
KeyboardInterrupt
Traceback (most recent call last):
  File "/usr/local/usrapps/ddomlab/sdehgha2/pls-dataset-env/lib/python3.10/site-packages/joblib/externals/loky/process_executor.py", line 463, in _process_worker
    r = call_item()
  File "/usr/local/usrapps/ddomlab/sdehgha2/pls-dataset-env/lib/python3.10/site-packages/joblib/externals/loky/process_executor.py", line 291, in __call__
    return self.fn(*self.args, **self.kwargs)
  File "/usr/local/usrapps/ddomlab/sdehgha2/pls-dataset-env/lib/python3.10/site-packages/joblib/parallel.py", line 598, in __call__
    return [func(*args, **kwargs)
  File "/usr/local/usrapps/ddomlab/sdehgha2/pls-dataset-env/lib/python3.10/site-packages/joblib/parallel.py", line 598, in <listcomp>
    return [func(*args, **kwargs)
  File "/usr/local/usrapps/ddomlab/sdehgha2/pls-dataset-env/lib/python3.10/site-packages/sklearn/utils/parallel.py", line 136, in __call__
    return self.function(*args, **kwargs)
  File "/usr/local/usrapps/ddomlab/sdehgha2/pls-dataset-env/lib/python3.10/site-packages/sklearn/model_selection/_validation.py", line 888, in _fit_and_score
    estimator.fit(X_train, y_train, **fit_params)
  File "/usr/local/usrapps/ddomlab/sdehgha2/pls-dataset-env/lib/python3.10/site-packages/sklearn/base.py", line 1473, in wrapper
    return fit_method(estimator, *args, **kwargs)
  File "/usr/local/usrapps/ddomlab/sdehgha2/pls-dataset-env/lib/python3.10/site-packages/sklearn/pipeline.py", line 473, in fit
    self._final_estimator.fit(Xt, y, **last_step_params["fit"])
  File "/usr/local/usrapps/ddomlab/sdehgha2/pls-dataset-env/lib/python3.10/site-packages/sklearn/base.py", line 1473, in wrapper
    return fit_method(estimator, *args, **kwargs)
  File "/usr/local/usrapps/ddomlab/sdehgha2/pls-dataset-env/lib/python3.10/site-packages/sklearn/compose/_target.py", line 288, in fit
    self.regressor_.fit(X, y_trans, **fit_params)
  File "/usr/local/usrapps/ddomlab/sdehgha2/pls-dataset-env/lib/python3.10/site-packages/sklearn/base.py", line 1473, in wrapper
    return fit_method(estimator, *args, **kwargs)
  File "/usr/local/usrapps/ddomlab/sdehgha2/pls-dataset-env/lib/python3.10/site-packages/sklearn/ensemble/_forest.py", line 489, in fit
    trees = Parallel(
  File "/usr/local/usrapps/ddomlab/sdehgha2/pls-dataset-env/lib/python3.10/site-packages/sklearn/utils/parallel.py", line 74, in __call__
    return super().__call__(iterable_with_config)
  File "/usr/local/usrapps/ddomlab/sdehgha2/pls-dataset-env/lib/python3.10/site-packages/joblib/parallel.py", line 1918, in __call__
    return output if self.return_generator else list(output)
  File "/usr/local/usrapps/ddomlab/sdehgha2/pls-dataset-env/lib/python3.10/site-packages/joblib/parallel.py", line 1847, in _get_sequential_output
    res = func(*args, **kwargs)
  File "/usr/local/usrapps/ddomlab/sdehgha2/pls-dataset-env/lib/python3.10/site-packages/sklearn/utils/parallel.py", line 136, in __call__
    return self.function(*args, **kwargs)
  File "/usr/local/usrapps/ddomlab/sdehgha2/pls-dataset-env/lib/python3.10/site-packages/sklearn/ensemble/_forest.py", line 192, in _parallel_build_trees
    tree._fit(
  File "/usr/local/usrapps/ddomlab/sdehgha2/pls-dataset-env/lib/python3.10/site-packages/sklearn/tree/_classes.py", line 239, in _fit
    random_state = check_random_state(self.random_state)
  File "/usr/local/usrapps/ddomlab/sdehgha2/pls-dataset-env/lib/python3.10/site-packages/sklearn/utils/validation.py", line 1436, in check_random_state
    return np.random.RandomState(seed)
  File "mtrand.pyx", line 184, in numpy.random.mtrand.RandomState.__init__
  File "_mt19937.pyx", line 130, in numpy.random._mt19937.MT19937.__init__
  File "/usr/local/usrapps/ddomlab/sdehgha2/pls-dataset-env/lib/python3.10/contextlib.py", line 79, in inner
    return func(*args, **kwds)
KeyboardInterrupt

During handling of the above exception, another exception occurred:

Traceback (most recent call last):
  File "/usr/local/usrapps/ddomlab/sdehgha2/pls-dataset-env/lib/python3.10/multiprocessing/process.py", line 314, in _bootstrap
    self.run()
  File "/usr/local/usrapps/ddomlab/sdehgha2/pls-dataset-env/lib/python3.10/multiprocessing/process.py", line 108, in run
    self._target(*self._args, **self._kwargs)
  File "/usr/local/usrapps/ddomlab/sdehgha2/pls-dataset-env/lib/python3.10/site-packages/joblib/externals/loky/process_executor.py", line 465, in _process_worker
    exc = _ExceptionWithTraceback(e)
  File "/usr/local/usrapps/ddomlab/sdehgha2/pls-dataset-env/lib/python3.10/site-packages/joblib/externals/loky/process_executor.py", line 247, in __init__
    tb = traceback.format_exception(type(exc), exc, tb)
  File "/usr/local/usrapps/ddomlab/sdehgha2/pls-dataset-env/lib/python3.10/traceback.py", line 124, in format_exception
    def format_exception(exc, /, value=_sentinel, tb=_sentinel, limit=None, \
KeyboardInterrupt
Traceback (most recent call last):
  File "/usr/local/usrapps/ddomlab/sdehgha2/pls-dataset-env/lib/python3.10/site-packages/joblib/externals/loky/process_executor.py", line 463, in _process_worker
    r = call_item()
  File "/usr/local/usrapps/ddomlab/sdehgha2/pls-dataset-env/lib/python3.10/site-packages/joblib/externals/loky/process_executor.py", line 291, in __call__
    return self.fn(*self.args, **self.kwargs)
  File "/usr/local/usrapps/ddomlab/sdehgha2/pls-dataset-env/lib/python3.10/site-packages/joblib/parallel.py", line 598, in __call__
    return [func(*args, **kwargs)
  File "/usr/local/usrapps/ddomlab/sdehgha2/pls-dataset-env/lib/python3.10/site-packages/joblib/parallel.py", line 598, in <listcomp>
    return [func(*args, **kwargs)
  File "/usr/local/usrapps/ddomlab/sdehgha2/pls-dataset-env/lib/python3.10/site-packages/sklearn/utils/parallel.py", line 136, in __call__
    return self.function(*args, **kwargs)
  File "/usr/local/usrapps/ddomlab/sdehgha2/pls-dataset-env/lib/python3.10/site-packages/sklearn/model_selection/_validation.py", line 888, in _fit_and_score
    estimator.fit(X_train, y_train, **fit_params)
  File "/usr/local/usrapps/ddomlab/sdehgha2/pls-dataset-env/lib/python3.10/site-packages/sklearn/base.py", line 1473, in wrapper
    return fit_method(estimator, *args, **kwargs)
  File "/usr/local/usrapps/ddomlab/sdehgha2/pls-dataset-env/lib/python3.10/site-packages/sklearn/pipeline.py", line 473, in fit
    self._final_estimator.fit(Xt, y, **last_step_params["fit"])
  File "/usr/local/usrapps/ddomlab/sdehgha2/pls-dataset-env/lib/python3.10/site-packages/sklearn/base.py", line 1473, in wrapper
    return fit_method(estimator, *args, **kwargs)
  File "/usr/local/usrapps/ddomlab/sdehgha2/pls-dataset-env/lib/python3.10/site-packages/sklearn/compose/_target.py", line 288, in fit
    self.regressor_.fit(X, y_trans, **fit_params)
  File "/usr/local/usrapps/ddomlab/sdehgha2/pls-dataset-env/lib/python3.10/site-packages/sklearn/base.py", line 1473, in wrapper
    return fit_method(estimator, *args, **kwargs)
  File "/usr/local/usrapps/ddomlab/sdehgha2/pls-dataset-env/lib/python3.10/site-packages/sklearn/ensemble/_forest.py", line 489, in fit
    trees = Parallel(
  File "/usr/local/usrapps/ddomlab/sdehgha2/pls-dataset-env/lib/python3.10/site-packages/sklearn/utils/parallel.py", line 74, in __call__
    return super().__call__(iterable_with_config)
  File "/usr/local/usrapps/ddomlab/sdehgha2/pls-dataset-env/lib/python3.10/site-packages/joblib/parallel.py", line 1918, in __call__
    return output if self.return_generator else list(output)
  File "/usr/local/usrapps/ddomlab/sdehgha2/pls-dataset-env/lib/python3.10/site-packages/joblib/parallel.py", line 1847, in _get_sequential_output
    res = func(*args, **kwargs)
  File "/usr/local/usrapps/ddomlab/sdehgha2/pls-dataset-env/lib/python3.10/site-packages/sklearn/utils/parallel.py", line 136, in __call__
    return self.function(*args, **kwargs)
  File "/usr/local/usrapps/ddomlab/sdehgha2/pls-dataset-env/lib/python3.10/site-packages/sklearn/ensemble/_forest.py", line 192, in _parallel_build_trees
    tree._fit(
  File "/usr/local/usrapps/ddomlab/sdehgha2/pls-dataset-env/lib/python3.10/site-packages/sklearn/tree/_classes.py", line 361, in _fit
    sample_weight = _check_sample_weight(sample_weight, X, DOUBLE)
  File "/usr/local/usrapps/ddomlab/sdehgha2/pls-dataset-env/lib/python3.10/site-packages/sklearn/utils/validation.py", line 2043, in _check_sample_weight
    sample_weight = check_array(
  File "/usr/local/usrapps/ddomlab/sdehgha2/pls-dataset-env/lib/python3.10/site-packages/sklearn/utils/validation.py", line 994, in check_array
    with warnings.catch_warnings():
  File "/usr/local/usrapps/ddomlab/sdehgha2/pls-dataset-env/lib/python3.10/warnings.py", line 437, in __init__
    def __init__(self, *, record=False, module=None):
KeyboardInterrupt

During handling of the above exception, another exception occurred:

Traceback (most recent call last):
  File "/usr/local/usrapps/ddomlab/sdehgha2/pls-dataset-env/lib/python3.10/multiprocessing/process.py", line 314, in _bootstrap
    self.run()
  File "/usr/local/usrapps/ddomlab/sdehgha2/pls-dataset-env/lib/python3.10/multiprocessing/process.py", line 108, in run
    self._target(*self._args, **self._kwargs)
  File "/usr/local/usrapps/ddomlab/sdehgha2/pls-dataset-env/lib/python3.10/site-packages/joblib/externals/loky/process_executor.py", line 465, in _process_worker
    exc = _ExceptionWithTraceback(e)
  File "/usr/local/usrapps/ddomlab/sdehgha2/pls-dataset-env/lib/python3.10/site-packages/joblib/externals/loky/process_executor.py", line 247, in __init__
    tb = traceback.format_exception(type(exc), exc, tb)
  File "/usr/local/usrapps/ddomlab/sdehgha2/pls-dataset-env/lib/python3.10/traceback.py", line 135, in format_exception
    te = TracebackException(type(value), value, tb, limit=limit, compact=True)
  File "/usr/local/usrapps/ddomlab/sdehgha2/pls-dataset-env/lib/python3.10/traceback.py", line 502, in __init__
    self.stack = StackSummary.extract(
  File "/usr/local/usrapps/ddomlab/sdehgha2/pls-dataset-env/lib/python3.10/traceback.py", line 370, in extract
    linecache.lazycache(filename, f.f_globals)
  File "/usr/local/usrapps/ddomlab/sdehgha2/pls-dataset-env/lib/python3.10/linecache.py", line 179, in lazycache
    get_lines = functools.partial(get_source, name)
KeyboardInterrupt
