Traceback (most recent call last):
  File "/gpfs_common/share03/ddomlab/sdehgha2/working-space/main/P1_pls-dataset/pls-dataset-space/PLS-Dataset/code_/training/hpc_submit_training_Rh/../train_numerical_only.py", line 163, in <module>
    main_numerical_only(
  File "/gpfs_common/share03/ddomlab/sdehgha2/working-space/main/P1_pls-dataset/pls-dataset-space/PLS-Dataset/code_/training/hpc_submit_training_Rh/../train_numerical_only.py", line 36, in main_numerical_only
    scores, predictions,data_shapes  = train_regressor(
  File "/gpfs_common/share03/ddomlab/sdehgha2/working-space/main/P1_pls-dataset/pls-dataset-space/PLS-Dataset/code_/training/training_utils.py", line 67, in train_regressor
    scores, predictions, data_shape = _prepare_data(
  File "/gpfs_common/share03/ddomlab/sdehgha2/working-space/main/P1_pls-dataset/pls-dataset-space/PLS-Dataset/code_/training/training_utils.py", line 137, in _prepare_data
    score,predication= run(
  File "/gpfs_common/share03/ddomlab/sdehgha2/working-space/main/P1_pls-dataset/pls-dataset-space/PLS-Dataset/code_/training/training_utils.py", line 169, in run
    y_transform = get_target_transformer(transform_type,target_name=target_features)
TypeError: get_target_transformer() got an unexpected keyword argument 'target_name'
/usr/local/usrapps/ddomlab/sdehgha2/pls-dataset-env/lib/python3.10/site-packages/skopt/optimizer/optimizer.py:517: UserWarning: The objective has been evaluated at point [None, 'log2', 0.99, 0.05, 2000] before, using random point [None, 'sqrt', 0.6165309456388386, 0.8272138435745372, 1649]
  warnings.warn(
/usr/local/usrapps/ddomlab/sdehgha2/pls-dataset-env/lib/python3.10/site-packages/skopt/optimizer/optimizer.py:517: UserWarning: The objective has been evaluated at point [None, 'log2', 0.99, 0.99, 2000] before, using random point [None, 'sqrt', 0.5394965812044591, 0.2154629058060828, 677]
  warnings.warn(
/usr/local/usrapps/ddomlab/sdehgha2/pls-dataset-env/lib/python3.10/site-packages/skopt/optimizer/optimizer.py:517: UserWarning: The objective has been evaluated at point [None, 'sqrt', 0.99, 0.05, 50] before, using random point [None, 'log2', 0.5260233261920714, 0.13188673643106974, 319]
  warnings.warn(
/usr/local/usrapps/ddomlab/sdehgha2/pls-dataset-env/lib/python3.10/site-packages/skopt/optimizer/optimizer.py:517: UserWarning: The objective has been evaluated at point [None, 'sqrt', 0.99, 0.05, 50] before, using random point [None, 'sqrt', 0.5730885714889555, 0.6510717690900344, 579]
  warnings.warn(
/usr/local/usrapps/ddomlab/sdehgha2/pls-dataset-env/lib/python3.10/site-packages/skopt/optimizer/optimizer.py:517: UserWarning: The objective has been evaluated at point [None, 'sqrt', 0.99, 0.05, 50] before, using random point [None, 'sqrt', 0.23423952122297692, 0.9083605015725394, 809]
  warnings.warn(
/usr/local/usrapps/ddomlab/sdehgha2/pls-dataset-env/lib/python3.10/site-packages/skopt/optimizer/optimizer.py:517: UserWarning: The objective has been evaluated at point [None, 'sqrt', 0.99, 0.05, 50] before, using random point [None, 'log2', 0.3437384566955023, 0.4757553851107251, 1473]
  warnings.warn(
/usr/local/usrapps/ddomlab/sdehgha2/pls-dataset-env/lib/python3.10/site-packages/skopt/optimizer/optimizer.py:517: UserWarning: The objective has been evaluated at point [None, 'sqrt', 0.99, 0.05, 50] before, using random point [None, 'log2', 0.2553316399824735, 0.36031715567028366, 94]
  warnings.warn(
/usr/local/usrapps/ddomlab/sdehgha2/pls-dataset-env/lib/python3.10/site-packages/skopt/optimizer/optimizer.py:517: UserWarning: The objective has been evaluated at point [None, 'sqrt', 0.99, 0.99, 50] before, using random point [None, 'log2', 0.8419483986636545, 0.7877854805066634, 180]
  warnings.warn(
/usr/local/usrapps/ddomlab/sdehgha2/pls-dataset-env/lib/python3.10/site-packages/skopt/optimizer/optimizer.py:517: UserWarning: The objective has been evaluated at point [None, 'sqrt', 0.99, 0.99, 50] before, using random point [None, 'sqrt', 0.19016076358185585, 0.8804695406408936, 1214]
  warnings.warn(
/usr/local/usrapps/ddomlab/sdehgha2/pls-dataset-env/lib/python3.10/site-packages/skopt/optimizer/optimizer.py:517: UserWarning: The objective has been evaluated at point [None, 'log2', 0.99, 0.99, 2000] before, using random point [None, 'sqrt', 0.9540110797408676, 0.29325395974927226, 74]
  warnings.warn(
/usr/local/usrapps/ddomlab/sdehgha2/pls-dataset-env/lib/python3.10/site-packages/skopt/optimizer/optimizer.py:517: UserWarning: The objective has been evaluated at point [None, 'log2', 0.99, 0.99, 50] before, using random point [None, 'log2', 0.5473889217489106, 0.602372740050466, 81]
  warnings.warn(
/usr/local/usrapps/ddomlab/sdehgha2/pls-dataset-env/lib/python3.10/site-packages/skopt/optimizer/optimizer.py:517: UserWarning: The objective has been evaluated at point [None, 'sqrt', 0.99, 0.05, 50] before, using random point [None, 'sqrt', 0.8921042091726975, 0.05217944433072608, 75]
  warnings.warn(
/usr/local/usrapps/ddomlab/sdehgha2/pls-dataset-env/lib/python3.10/site-packages/skopt/optimizer/optimizer.py:517: UserWarning: The objective has been evaluated at point [None, 'log2', 0.99, 0.99, 50] before, using random point [None, 'sqrt', 0.9133973488713009, 0.8569603261295692, 271]
  warnings.warn(
/usr/local/usrapps/ddomlab/sdehgha2/pls-dataset-env/lib/python3.10/site-packages/skopt/optimizer/optimizer.py:517: UserWarning: The objective has been evaluated at point [None, 'sqrt', 0.99, 0.99, 50] before, using random point [None, 'log2', 0.8035272247205374, 0.20570589287651575, 954]
  warnings.warn(
/usr/local/usrapps/ddomlab/sdehgha2/pls-dataset-env/lib/python3.10/site-packages/skopt/optimizer/optimizer.py:517: UserWarning: The objective has been evaluated at point [None, 'log2', 0.99, 0.99, 50] before, using random point [None, 'sqrt', 0.8420463860142221, 0.4495967186167607, 408]
  warnings.warn(
/usr/local/usrapps/ddomlab/sdehgha2/pls-dataset-env/lib/python3.10/site-packages/skopt/optimizer/optimizer.py:517: UserWarning: The objective has been evaluated at point [None, 'log2', 0.99, 0.99, 50] before, using random point [None, 'sqrt', 0.900767336009074, 0.7999104407139753, 53]
  warnings.warn(
/usr/local/usrapps/ddomlab/sdehgha2/pls-dataset-env/lib/python3.10/site-packages/skopt/optimizer/optimizer.py:517: UserWarning: The objective has been evaluated at point [None, 'sqrt', 0.99, 0.99, 50] before, using random point [None, 'sqrt', 0.38154906784765547, 0.503204406658605, 458]
  warnings.warn(
/usr/local/usrapps/ddomlab/sdehgha2/pls-dataset-env/lib/python3.10/site-packages/skopt/optimizer/optimizer.py:517: UserWarning: The objective has been evaluated at point [None, 'sqrt', 0.99, 0.99, 50] before, using random point [None, 'sqrt', 0.9701717052520691, 0.25347424389834167, 1069]
  warnings.warn(
/usr/local/usrapps/ddomlab/sdehgha2/pls-dataset-env/lib/python3.10/site-packages/skopt/optimizer/optimizer.py:517: UserWarning: The objective has been evaluated at point [None, 'sqrt', 0.99, 0.99, 50] before, using random point [None, 'sqrt', 0.21308470768734078, 0.6091695944007677, 222]
  warnings.warn(
/usr/local/usrapps/ddomlab/sdehgha2/pls-dataset-env/lib/python3.10/site-packages/skopt/optimizer/optimizer.py:517: UserWarning: The objective has been evaluated at point [None, 'sqrt', 0.05, 0.99, 2000] before, using random point [None, 'log2', 0.09282623266056494, 0.7115190296638978, 1485]
  warnings.warn(
/usr/local/usrapps/ddomlab/sdehgha2/pls-dataset-env/lib/python3.10/site-packages/skopt/optimizer/optimizer.py:517: UserWarning: The objective has been evaluated at point [None, 'sqrt', 0.05, 0.99, 50] before, using random point [None, 'sqrt', 0.1892064049915163, 0.47469856817163575, 258]
  warnings.warn(
/usr/local/usrapps/ddomlab/sdehgha2/pls-dataset-env/lib/python3.10/site-packages/skopt/optimizer/optimizer.py:517: UserWarning: The objective has been evaluated at point [None, 'log2', 0.99, 0.05, 50] before, using random point [None, 'sqrt', 0.7155213820977265, 0.1927129759666823, 442]
  warnings.warn(
/usr/local/usrapps/ddomlab/sdehgha2/pls-dataset-env/lib/python3.10/site-packages/skopt/optimizer/optimizer.py:517: UserWarning: The objective has been evaluated at point [None, 'log2', 0.99, 0.05, 50] before, using random point [None, 'log2', 0.6868719466839603, 0.8512232719185623, 602]
  warnings.warn(
/usr/local/usrapps/ddomlab/sdehgha2/pls-dataset-env/lib/python3.10/site-packages/skopt/optimizer/optimizer.py:517: UserWarning: The objective has been evaluated at point [None, 'log2', 0.99, 0.05, 50] before, using random point [None, 'sqrt', 0.16688860838059272, 0.2950884884576261, 217]
  warnings.warn(
/usr/local/usrapps/ddomlab/sdehgha2/pls-dataset-env/lib/python3.10/site-packages/skopt/optimizer/optimizer.py:517: UserWarning: The objective has been evaluated at point [None, 'log2', 0.99, 0.05, 50] before, using random point [None, 'log2', 0.45778326538481995, 0.298061103435407, 137]
  warnings.warn(
/usr/local/usrapps/ddomlab/sdehgha2/pls-dataset-env/lib/python3.10/site-packages/skopt/optimizer/optimizer.py:517: UserWarning: The objective has been evaluated at point [None, 'log2', 0.99, 0.05, 50] before, using random point [None, 'log2', 0.8362960267780664, 0.931908988751619, 69]
  warnings.warn(
/usr/local/usrapps/ddomlab/sdehgha2/pls-dataset-env/lib/python3.10/site-packages/skopt/optimizer/optimizer.py:517: UserWarning: The objective has been evaluated at point [None, 'log2', 0.99, 0.05, 50] before, using random point [None, 'sqrt', 0.7240887528511813, 0.45988683831336136, 62]
  warnings.warn(
/usr/local/usrapps/ddomlab/sdehgha2/pls-dataset-env/lib/python3.10/site-packages/skopt/optimizer/optimizer.py:517: UserWarning: The objective has been evaluated at point [None, 'sqrt', 0.99, 0.99, 50] before, using random point [None, 'log2', 0.1410749907929226, 0.7285699610731264, 1116]
  warnings.warn(
/usr/local/usrapps/ddomlab/sdehgha2/pls-dataset-env/lib/python3.10/site-packages/skopt/optimizer/optimizer.py:517: UserWarning: The objective has been evaluated at point [None, 'log2', 0.99, 0.05, 50] before, using random point [None, 'log2', 0.4346807357968955, 0.6353736756698436, 406]
  warnings.warn(
/usr/local/usrapps/ddomlab/sdehgha2/pls-dataset-env/lib/python3.10/site-packages/skopt/optimizer/optimizer.py:517: UserWarning: The objective has been evaluated at point [None, 'log2', 0.99, 0.05, 50] before, using random point [None, 'log2', 0.7682638459772545, 0.9190484915134336, 1089]
  warnings.warn(
/usr/local/usrapps/ddomlab/sdehgha2/pls-dataset-env/lib/python3.10/site-packages/skopt/optimizer/optimizer.py:517: UserWarning: The objective has been evaluated at point [None, 'sqrt', 0.99, 0.05, 50] before, using random point [None, 'sqrt', 0.6399555762050525, 0.2349216277448845, 216]
  warnings.warn(
/usr/local/usrapps/ddomlab/sdehgha2/pls-dataset-env/lib/python3.10/site-packages/skopt/optimizer/optimizer.py:517: UserWarning: The objective has been evaluated at point [None, 'sqrt', 0.99, 0.05, 50] before, using random point [None, 'sqrt', 0.31494719074886923, 0.38878128598413597, 1752]
  warnings.warn(
/usr/local/usrapps/ddomlab/sdehgha2/pls-dataset-env/lib/python3.10/site-packages/skopt/optimizer/optimizer.py:517: UserWarning: The objective has been evaluated at point [None, 'sqrt', 0.99, 0.05, 50] before, using random point [None, 'log2', 0.6364018152144345, 0.5160030795860555, 130]
  warnings.warn(
/usr/local/usrapps/ddomlab/sdehgha2/pls-dataset-env/lib/python3.10/site-packages/skopt/optimizer/optimizer.py:517: UserWarning: The objective has been evaluated at point [None, 'log2', 0.99, 0.05, 50] before, using random point [None, 'log2', 0.6196104680056134, 0.0818172575001081, 1226]
  warnings.warn(
/usr/local/usrapps/ddomlab/sdehgha2/pls-dataset-env/lib/python3.10/site-packages/skopt/optimizer/optimizer.py:517: UserWarning: The objective has been evaluated at point [None, 'log2', 0.99, 0.05, 50] before, using random point [None, 'log2', 0.12453301957878066, 0.53387648673979, 665]
  warnings.warn(
Process LokyProcess-2:
Process LokyProcess-14:
Traceback (most recent call last):
  File "/usr/local/usrapps/ddomlab/sdehgha2/pls-dataset-env/lib/python3.10/site-packages/joblib/externals/loky/process_executor.py", line 426, in _process_worker
    call_item = call_queue.get(block=True, timeout=timeout)
  File "/usr/local/usrapps/ddomlab/sdehgha2/pls-dataset-env/lib/python3.10/multiprocessing/queues.py", line 108, in get
    if not self._rlock.acquire(block, timeout):
Process LokyProcess-1:
KeyboardInterrupt

During handling of the above exception, another exception occurred:

Traceback (most recent call last):
  File "/usr/local/usrapps/ddomlab/sdehgha2/pls-dataset-env/lib/python3.10/multiprocessing/process.py", line 314, in _bootstrap
    self.run()
  File "/usr/local/usrapps/ddomlab/sdehgha2/pls-dataset-env/lib/python3.10/multiprocessing/process.py", line 108, in run
    self._target(*self._args, **self._kwargs)
  File "/usr/local/usrapps/ddomlab/sdehgha2/pls-dataset-env/lib/python3.10/site-packages/joblib/externals/loky/process_executor.py", line 426, in _process_worker
    call_item = call_queue.get(block=True, timeout=timeout)
KeyboardInterrupt
Traceback (most recent call last):
  File "/usr/local/usrapps/ddomlab/sdehgha2/pls-dataset-env/lib/python3.10/site-packages/joblib/externals/loky/process_executor.py", line 426, in _process_worker
    call_item = call_queue.get(block=True, timeout=timeout)
  File "/usr/local/usrapps/ddomlab/sdehgha2/pls-dataset-env/lib/python3.10/multiprocessing/queues.py", line 108, in get
    if not self._rlock.acquire(block, timeout):
KeyboardInterrupt

During handling of the above exception, another exception occurred:

Traceback (most recent call last):
  File "/usr/local/usrapps/ddomlab/sdehgha2/pls-dataset-env/lib/python3.10/multiprocessing/process.py", line 314, in _bootstrap
    self.run()
  File "/usr/local/usrapps/ddomlab/sdehgha2/pls-dataset-env/lib/python3.10/multiprocessing/process.py", line 108, in run
    self._target(*self._args, **self._kwargs)
  File "/usr/local/usrapps/ddomlab/sdehgha2/pls-dataset-env/lib/python3.10/site-packages/joblib/externals/loky/process_executor.py", line 438, in _process_worker
    previous_tb = traceback.format_exc()
  File "/usr/local/usrapps/ddomlab/sdehgha2/pls-dataset-env/lib/python3.10/traceback.py", line 183, in format_exc
    return "".join(format_exception(*sys.exc_info(), limit=limit, chain=chain))
  File "/usr/local/usrapps/ddomlab/sdehgha2/pls-dataset-env/lib/python3.10/traceback.py", line 135, in format_exception
    te = TracebackException(type(value), value, tb, limit=limit, compact=True)
  File "/usr/local/usrapps/ddomlab/sdehgha2/pls-dataset-env/lib/python3.10/traceback.py", line 502, in __init__
    self.stack = StackSummary.extract(
  File "/usr/local/usrapps/ddomlab/sdehgha2/pls-dataset-env/lib/python3.10/traceback.py", line 376, in extract
    result.append(FrameSummary(
KeyboardInterrupt
Traceback (most recent call last):
  File "/usr/local/usrapps/ddomlab/sdehgha2/pls-dataset-env/lib/python3.10/site-packages/joblib/externals/loky/process_executor.py", line 426, in _process_worker
    call_item = call_queue.get(block=True, timeout=timeout)
  File "/usr/local/usrapps/ddomlab/sdehgha2/pls-dataset-env/lib/python3.10/multiprocessing/queues.py", line 108, in get
    if not self._rlock.acquire(block, timeout):
KeyboardInterrupt

During handling of the above exception, another exception occurred:

Traceback (most recent call last):
  File "/usr/local/usrapps/ddomlab/sdehgha2/pls-dataset-env/lib/python3.10/multiprocessing/process.py", line 314, in _bootstrap
    self.run()
  File "/usr/local/usrapps/ddomlab/sdehgha2/pls-dataset-env/lib/python3.10/multiprocessing/process.py", line 108, in run
    self._target(*self._args, **self._kwargs)
  File "/usr/local/usrapps/ddomlab/sdehgha2/pls-dataset-env/lib/python3.10/site-packages/joblib/externals/loky/process_executor.py", line 438, in _process_worker
    previous_tb = traceback.format_exc()
  File "/usr/local/usrapps/ddomlab/sdehgha2/pls-dataset-env/lib/python3.10/traceback.py", line 181, in format_exc
    def format_exc(limit=None, chain=True):
KeyboardInterrupt
Traceback (most recent call last):
  File "/usr/local/usrapps/ddomlab/sdehgha2/pls-dataset-env/lib/python3.10/site-packages/sklearn/model_selection/_search.py", line 1019, in fit
    self._run_search(evaluate_candidates)
  File "/usr/local/usrapps/ddomlab/sdehgha2/pls-dataset-env/lib/python3.10/site-packages/skopt/searchcv.py", line 599, in _run_search
    optim_result, score_name = self._step(
  File "/usr/local/usrapps/ddomlab/sdehgha2/pls-dataset-env/lib/python3.10/site-packages/skopt/searchcv.py", line 445, in _step
    params = optimizer.ask(n_points=n_points)
  File "/usr/local/usrapps/ddomlab/sdehgha2/pls-dataset-env/lib/python3.10/site-packages/skopt/optimizer/optimizer.py", line 438, in ask
    opt = self.copy(random_state=self.rng.randint(0, np.iinfo(np.int32).max))
  File "/usr/local/usrapps/ddomlab/sdehgha2/pls-dataset-env/lib/python3.10/site-packages/skopt/optimizer/optimizer.py", line 380, in copy
    optimizer._tell(self.Xi, self.yi)
  File "/usr/local/usrapps/ddomlab/sdehgha2/pls-dataset-env/lib/python3.10/site-packages/skopt/optimizer/optimizer.py", line 657, in _tell
    results = Parallel(n_jobs=self.n_jobs)(
  File "/usr/local/usrapps/ddomlab/sdehgha2/pls-dataset-env/lib/python3.10/site-packages/joblib/parallel.py", line 1918, in __call__
    return output if self.return_generator else list(output)
  File "/usr/local/usrapps/ddomlab/sdehgha2/pls-dataset-env/lib/python3.10/site-packages/joblib/parallel.py", line 1847, in _get_sequential_output
    res = func(*args, **kwargs)
  File "/usr/local/usrapps/ddomlab/sdehgha2/pls-dataset-env/lib/python3.10/site-packages/scipy/optimize/_lbfgsb_py.py", line 237, in fmin_l_bfgs_b
    res = _minimize_lbfgsb(fun, x0, args=args, jac=jac, bounds=bounds,
  File "/usr/local/usrapps/ddomlab/sdehgha2/pls-dataset-env/lib/python3.10/site-packages/scipy/optimize/_lbfgsb_py.py", line 407, in _minimize_lbfgsb
    f, g = func_and_grad(x)
  File "/usr/local/usrapps/ddomlab/sdehgha2/pls-dataset-env/lib/python3.10/site-packages/scipy/optimize/_differentiable_functions.py", line 343, in fun_and_grad
    self._update_fun()
  File "/usr/local/usrapps/ddomlab/sdehgha2/pls-dataset-env/lib/python3.10/site-packages/scipy/optimize/_differentiable_functions.py", line 294, in _update_fun
    fx = self._wrapped_fun(self.x)
  File "/usr/local/usrapps/ddomlab/sdehgha2/pls-dataset-env/lib/python3.10/site-packages/scipy/optimize/_differentiable_functions.py", line 20, in wrapped
    fx = fun(np.copy(x), *args)
  File "/usr/local/usrapps/ddomlab/sdehgha2/pls-dataset-env/lib/python3.10/site-packages/scipy/optimize/_optimize.py", line 79, in __call__
    self._compute_if_needed(x, *args)
  File "/usr/local/usrapps/ddomlab/sdehgha2/pls-dataset-env/lib/python3.10/site-packages/scipy/optimize/_optimize.py", line 73, in _compute_if_needed
    fg = self.fun(x, *args)
  File "/usr/local/usrapps/ddomlab/sdehgha2/pls-dataset-env/lib/python3.10/site-packages/skopt/acquisition.py", line 16, in gaussian_acquisition_1D
    return _gaussian_acquisition(
  File "/usr/local/usrapps/ddomlab/sdehgha2/pls-dataset-env/lib/python3.10/site-packages/skopt/acquisition.py", line 61, in _gaussian_acquisition
    func_and_grad = gaussian_pi(X, model, y_opt, xi, return_grad)
  File "/usr/local/usrapps/ddomlab/sdehgha2/pls-dataset-env/lib/python3.10/site-packages/skopt/acquisition.py", line 242, in gaussian_pi
    return values, improve_grad * norm.pdf(scaled)
  File "/usr/local/usrapps/ddomlab/sdehgha2/pls-dataset-env/lib/python3.10/site-packages/scipy/stats/_distn_infrastructure.py", line 2002, in pdf
    def pdf(self, x, *args, **kwds):
KeyboardInterrupt

During handling of the above exception, another exception occurred:

Traceback (most recent call last):
  File "/gpfs_common/share03/ddomlab/sdehgha2/working-space/main/P1_pls-dataset/pls-dataset-space/PLS-Dataset/code_/training/hpc_submit_training_Rh/../train_numerical_only.py", line 163, in <module>
    main_numerical_only(
  File "/gpfs_common/share03/ddomlab/sdehgha2/working-space/main/P1_pls-dataset/pls-dataset-space/PLS-Dataset/code_/training/hpc_submit_training_Rh/../train_numerical_only.py", line 36, in main_numerical_only
    scores, predictions,data_shapes  = train_regressor(
  File "/gpfs_common/share03/ddomlab/sdehgha2/working-space/main/P1_pls-dataset/pls-dataset-space/PLS-Dataset/code_/training/training_utils.py", line 67, in train_regressor
    scores, predictions, data_shape = _prepare_data(
  File "/gpfs_common/share03/ddomlab/sdehgha2/working-space/main/P1_pls-dataset/pls-dataset-space/PLS-Dataset/code_/training/training_utils.py", line 137, in _prepare_data
    score,predication= run(
  File "/gpfs_common/share03/ddomlab/sdehgha2/working-space/main/P1_pls-dataset/pls-dataset-space/PLS-Dataset/code_/training/training_utils.py", line 199, in run
    best_estimator, regressor_params = _optimize_hyperparams(
  File "/gpfs_common/share03/ddomlab/sdehgha2/working-space/main/P1_pls-dataset/pls-dataset-space/PLS-Dataset/code_/training/training_utils.py", line 265, in _optimize_hyperparams
    bayes.fit(X_train, y_train)
  File "/usr/local/usrapps/ddomlab/sdehgha2/pls-dataset-env/lib/python3.10/site-packages/skopt/searchcv.py", line 542, in fit
    super().fit(X=X, y=y, groups=groups, **fit_params)
  File "/usr/local/usrapps/ddomlab/sdehgha2/pls-dataset-env/lib/python3.10/site-packages/sklearn/base.py", line 1473, in wrapper
    return fit_method(estimator, *args, **kwargs)
  File "/usr/local/usrapps/ddomlab/sdehgha2/pls-dataset-env/lib/python3.10/site-packages/sklearn/model_selection/_search.py", line 947, in fit
    with parallel:
  File "/usr/local/usrapps/ddomlab/sdehgha2/pls-dataset-env/lib/python3.10/site-packages/joblib/parallel.py", line 1354, in __exit__
    self._terminate_and_reset()
  File "/usr/local/usrapps/ddomlab/sdehgha2/pls-dataset-env/lib/python3.10/site-packages/joblib/parallel.py", line 1386, in _terminate_and_reset
    self._backend.terminate()
  File "/usr/local/usrapps/ddomlab/sdehgha2/pls-dataset-env/lib/python3.10/site-packages/joblib/_parallel_backends.py", line 610, in terminate
    self._workers._temp_folder_manager._clean_temporary_resources(
  File "/usr/local/usrapps/ddomlab/sdehgha2/pls-dataset-env/lib/python3.10/site-packages/joblib/_memmapping_reducer.py", line 608, in _clean_temporary_resources
    def _clean_temporary_resources(self, context_id=None, force=False,
KeyboardInterrupt
/usr/local/usrapps/ddomlab/sdehgha2/pls-dataset-env/lib/python3.10/site-packages/skopt/optimizer/optimizer.py:517: UserWarning: The objective has been evaluated at point [None, 'log2', 0.05, 0.99, 50] before, using random point [None, 'log2', 0.7046663188103167, 0.8378392382840412, 402]
  warnings.warn(
/usr/local/usrapps/ddomlab/sdehgha2/pls-dataset-env/lib/python3.10/site-packages/skopt/optimizer/optimizer.py:517: UserWarning: The objective has been evaluated at point [None, 'sqrt', 0.05, 0.99, 50] before, using random point [None, 'log2', 0.2569620574823542, 0.45933127291425463, 81]
  warnings.warn(
/usr/local/usrapps/ddomlab/sdehgha2/pls-dataset-env/lib/python3.10/site-packages/skopt/optimizer/optimizer.py:517: UserWarning: The objective has been evaluated at point [None, 'sqrt', 0.05, 0.99, 50] before, using random point [None, 'sqrt', 0.48709798996256753, 0.8757520438345913, 129]
  warnings.warn(
/usr/local/usrapps/ddomlab/sdehgha2/pls-dataset-env/lib/python3.10/site-packages/skopt/optimizer/optimizer.py:517: UserWarning: The objective has been evaluated at point [None, 'sqrt', 0.99, 0.99, 2000] before, using random point [None, 'log2', 0.1509450343969257, 0.6691592150982739, 148]
  warnings.warn(
/usr/local/usrapps/ddomlab/sdehgha2/pls-dataset-env/lib/python3.10/site-packages/skopt/optimizer/optimizer.py:517: UserWarning: The objective has been evaluated at point [None, 'log2', 0.99, 0.05, 50] before, using random point [None, 'sqrt', 0.06364244687259585, 0.5317229206372015, 251]
  warnings.warn(
/usr/local/usrapps/ddomlab/sdehgha2/pls-dataset-env/lib/python3.10/site-packages/skopt/optimizer/optimizer.py:517: UserWarning: The objective has been evaluated at point [None, 'log2', 0.99, 0.05, 50] before, using random point [None, 'sqrt', 0.21904606968367102, 0.08421141964650725, 360]
  warnings.warn(
/usr/local/usrapps/ddomlab/sdehgha2/pls-dataset-env/lib/python3.10/site-packages/skopt/optimizer/optimizer.py:517: UserWarning: The objective has been evaluated at point [None, 'log2', 0.99, 0.05, 50] before, using random point [None, 'log2', 0.146449935379605, 0.05641241268091024, 65]
  warnings.warn(
/usr/local/usrapps/ddomlab/sdehgha2/pls-dataset-env/lib/python3.10/site-packages/skopt/optimizer/optimizer.py:517: UserWarning: The objective has been evaluated at point [None, 'log2', 0.99, 0.05, 50] before, using random point [None, 'log2', 0.06394663863244435, 0.5743284233594455, 121]
  warnings.warn(
/usr/local/usrapps/ddomlab/sdehgha2/pls-dataset-env/lib/python3.10/site-packages/skopt/optimizer/optimizer.py:517: UserWarning: The objective has been evaluated at point [None, 'sqrt', 0.05, 0.99, 2000] before, using random point [None, 'sqrt', 0.9121605897267945, 0.6610705280452258, 280]
  warnings.warn(
/usr/local/usrapps/ddomlab/sdehgha2/pls-dataset-env/lib/python3.10/site-packages/skopt/optimizer/optimizer.py:517: UserWarning: The objective has been evaluated at point [None, 'sqrt', 0.99, 0.05, 2000] before, using random point [None, 'sqrt', 0.7509929447104872, 0.6990852334812857, 218]
  warnings.warn(
/usr/local/usrapps/ddomlab/sdehgha2/pls-dataset-env/lib/python3.10/site-packages/skopt/optimizer/optimizer.py:517: UserWarning: The objective has been evaluated at point [None, 'sqrt', 0.99, 0.05, 2000] before, using random point [None, 'log2', 0.8590204666284401, 0.3458030776837378, 141]
  warnings.warn(
/usr/local/usrapps/ddomlab/sdehgha2/pls-dataset-env/lib/python3.10/site-packages/skopt/optimizer/optimizer.py:517: UserWarning: The objective has been evaluated at point [None, 'log2', 0.99, 0.05, 2000] before, using random point [None, 'log2', 0.9081445077352573, 0.620054554192778, 127]
  warnings.warn(
/usr/local/usrapps/ddomlab/sdehgha2/pls-dataset-env/lib/python3.10/site-packages/skopt/optimizer/optimizer.py:517: UserWarning: The objective has been evaluated at point [None, 'log2', 0.99, 0.05, 2000] before, using random point [None, 'log2', 0.9218262655860088, 0.10129149261807646, 56]
  warnings.warn(
/usr/local/usrapps/ddomlab/sdehgha2/pls-dataset-env/lib/python3.10/site-packages/skopt/optimizer/optimizer.py:517: UserWarning: The objective has been evaluated at point [None, 'log2', 0.99, 0.05, 2000] before, using random point [None, 'sqrt', 0.758849394965188, 0.8788016484457115, 277]
  warnings.warn(
/usr/local/usrapps/ddomlab/sdehgha2/pls-dataset-env/lib/python3.10/site-packages/skopt/optimizer/optimizer.py:517: UserWarning: The objective has been evaluated at point [None, 'log2', 0.99, 0.05, 2000] before, using random point [None, 'sqrt', 0.6399555762050525, 0.2349216277448845, 216]
  warnings.warn(
/usr/local/usrapps/ddomlab/sdehgha2/pls-dataset-env/lib/python3.10/site-packages/skopt/optimizer/optimizer.py:517: UserWarning: The objective has been evaluated at point [None, 'log2', 0.99, 0.05, 2000] before, using random point [None, 'sqrt', 0.31494719074886923, 0.38878128598413597, 1752]
  warnings.warn(
/usr/local/usrapps/ddomlab/sdehgha2/pls-dataset-env/lib/python3.10/site-packages/skopt/optimizer/optimizer.py:517: UserWarning: The objective has been evaluated at point [None, 'log2', 0.99, 0.05, 2000] before, using random point [None, 'log2', 0.6364018152144345, 0.5160030795860555, 130]
  warnings.warn(
