Process LokyProcess-21:
Process LokyProcess-2:
Process LokyProcess-1:
Process LokyProcess-11:
Process LokyProcess-10:
Process LokyProcess-17:
Traceback (most recent call last):
  File "/usr/local/usrapps/ddomlab/sdehgha2/pls-dataset-env/lib/python3.10/site-packages/joblib/parallel.py", line 1650, in _get_outputs
Traceback (most recent call last):
  File "/usr/local/usrapps/ddomlab/sdehgha2/pls-dataset-env/lib/python3.10/site-packages/joblib/externals/loky/process_executor.py", line 426, in _process_worker
    call_item = call_queue.get(block=True, timeout=timeout)
  File "/usr/local/usrapps/ddomlab/sdehgha2/pls-dataset-env/lib/python3.10/multiprocessing/queues.py", line 108, in get
    if not self._rlock.acquire(block, timeout):
Traceback (most recent call last):
  File "/usr/local/usrapps/ddomlab/sdehgha2/pls-dataset-env/lib/python3.10/site-packages/joblib/externals/loky/process_executor.py", line 426, in _process_worker
    call_item = call_queue.get(block=True, timeout=timeout)
  File "/usr/local/usrapps/ddomlab/sdehgha2/pls-dataset-env/lib/python3.10/multiprocessing/queues.py", line 108, in get
    if not self._rlock.acquire(block, timeout):
KeyboardInterrupt

During handling of the above exception, another exception occurred:

Traceback (most recent call last):
  File "/usr/local/usrapps/ddomlab/sdehgha2/pls-dataset-env/lib/python3.10/multiprocessing/process.py", line 314, in _bootstrap
    self.run()
  File "/usr/local/usrapps/ddomlab/sdehgha2/pls-dataset-env/lib/python3.10/multiprocessing/process.py", line 108, in run
    self._target(*self._args, **self._kwargs)
  File "/usr/local/usrapps/ddomlab/sdehgha2/pls-dataset-env/lib/python3.10/site-packages/joblib/externals/loky/process_executor.py", line 438, in _process_worker
    previous_tb = traceback.format_exc()
  File "/usr/local/usrapps/ddomlab/sdehgha2/pls-dataset-env/lib/python3.10/traceback.py", line 183, in format_exc
    return "".join(format_exception(*sys.exc_info(), limit=limit, chain=chain))
  File "/usr/local/usrapps/ddomlab/sdehgha2/pls-dataset-env/lib/python3.10/traceback.py", line 135, in format_exception
    te = TracebackException(type(value), value, tb, limit=limit, compact=True)
  File "/usr/local/usrapps/ddomlab/sdehgha2/pls-dataset-env/lib/python3.10/traceback.py", line 489, in __init__
    def __init__(self, exc_type, exc_value, exc_traceback, *, limit=None,
KeyboardInterrupt
Traceback (most recent call last):
  File "/usr/local/usrapps/ddomlab/sdehgha2/pls-dataset-env/lib/python3.10/site-packages/joblib/externals/loky/process_executor.py", line 426, in _process_worker
    call_item = call_queue.get(block=True, timeout=timeout)
  File "/usr/local/usrapps/ddomlab/sdehgha2/pls-dataset-env/lib/python3.10/multiprocessing/queues.py", line 108, in get
    if not self._rlock.acquire(block, timeout):
KeyboardInterrupt

During handling of the above exception, another exception occurred:

Traceback (most recent call last):
  File "/usr/local/usrapps/ddomlab/sdehgha2/pls-dataset-env/lib/python3.10/multiprocessing/process.py", line 314, in _bootstrap
    self.run()
  File "/usr/local/usrapps/ddomlab/sdehgha2/pls-dataset-env/lib/python3.10/multiprocessing/process.py", line 108, in run
    self._target(*self._args, **self._kwargs)
  File "/usr/local/usrapps/ddomlab/sdehgha2/pls-dataset-env/lib/python3.10/site-packages/joblib/externals/loky/process_executor.py", line 438, in _process_worker
    previous_tb = traceback.format_exc()
  File "/usr/local/usrapps/ddomlab/sdehgha2/pls-dataset-env/lib/python3.10/traceback.py", line 181, in format_exc
    def format_exc(limit=None, chain=True):
KeyboardInterrupt
KeyboardInterrupt

During handling of the above exception, another exception occurred:

Traceback (most recent call last):
  File "/usr/local/usrapps/ddomlab/sdehgha2/pls-dataset-env/lib/python3.10/multiprocessing/process.py", line 314, in _bootstrap
    self.run()
  File "/usr/local/usrapps/ddomlab/sdehgha2/pls-dataset-env/lib/python3.10/multiprocessing/process.py", line 108, in run
    self._target(*self._args, **self._kwargs)
  File "/usr/local/usrapps/ddomlab/sdehgha2/pls-dataset-env/lib/python3.10/site-packages/joblib/externals/loky/process_executor.py", line 426, in _process_worker
    call_item = call_queue.get(block=True, timeout=timeout)
KeyboardInterrupt
    yield from self._retrieve()
  File "/usr/local/usrapps/ddomlab/sdehgha2/pls-dataset-env/lib/python3.10/site-packages/joblib/parallel.py", line 1762, in _retrieve
Traceback (most recent call last):
  File "/usr/local/usrapps/ddomlab/sdehgha2/pls-dataset-env/lib/python3.10/site-packages/joblib/externals/loky/process_executor.py", line 426, in _process_worker
    call_item = call_queue.get(block=True, timeout=timeout)
  File "/usr/local/usrapps/ddomlab/sdehgha2/pls-dataset-env/lib/python3.10/multiprocessing/queues.py", line 108, in get
    if not self._rlock.acquire(block, timeout):
KeyboardInterrupt

During handling of the above exception, another exception occurred:

Traceback (most recent call last):
  File "/usr/local/usrapps/ddomlab/sdehgha2/pls-dataset-env/lib/python3.10/multiprocessing/process.py", line 314, in _bootstrap
    self.run()
  File "/usr/local/usrapps/ddomlab/sdehgha2/pls-dataset-env/lib/python3.10/multiprocessing/process.py", line 108, in run
    self._target(*self._args, **self._kwargs)
  File "/usr/local/usrapps/ddomlab/sdehgha2/pls-dataset-env/lib/python3.10/site-packages/joblib/externals/loky/process_executor.py", line 438, in _process_worker
    previous_tb = traceback.format_exc()
  File "/usr/local/usrapps/ddomlab/sdehgha2/pls-dataset-env/lib/python3.10/traceback.py", line 183, in format_exc
    return "".join(format_exception(*sys.exc_info(), limit=limit, chain=chain))
  File "/usr/local/usrapps/ddomlab/sdehgha2/pls-dataset-env/lib/python3.10/traceback.py", line 135, in format_exception
    te = TracebackException(type(value), value, tb, limit=limit, compact=True)
  File "/usr/local/usrapps/ddomlab/sdehgha2/pls-dataset-env/lib/python3.10/traceback.py", line 502, in __init__
    self.stack = StackSummary.extract(
  File "/usr/local/usrapps/ddomlab/sdehgha2/pls-dataset-env/lib/python3.10/traceback.py", line 369, in extract
    fnames.add(filename)
KeyboardInterrupt
    time.sleep(0.01)
KeyboardInterrupt

During handling of the above exception, another exception occurred:

Traceback (most recent call last):
  File "/gpfs_common/share03/ddomlab/sdehgha2/working-space/main/P1_pls-dataset/pls-dataset-space/PLS-Dataset/code_/training/hpc_submit_training_Rh/../train_structure_numerical.py", line 216, in <module>
    main_structural_numerical(
  File "/gpfs_common/share03/ddomlab/sdehgha2/working-space/main/P1_pls-dataset/pls-dataset-space/PLS-Dataset/code_/training/hpc_submit_training_Rh/../train_structure_numerical.py", line 66, in main_structural_numerical
    scores, predictions,data_shapes  = train_regressor(
  File "/gpfs_common/share03/ddomlab/sdehgha2/working-space/main/P1_pls-dataset/pls-dataset-space/PLS-Dataset/code_/training/training_utils.py", line 67, in train_regressor
    scores, predictions, data_shape = _prepare_data(
  File "/gpfs_common/share03/ddomlab/sdehgha2/working-space/main/P1_pls-dataset/pls-dataset-space/PLS-Dataset/code_/training/training_utils.py", line 138, in _prepare_data
    score,predication= run(
  File "/gpfs_common/share03/ddomlab/sdehgha2/working-space/main/P1_pls-dataset/pls-dataset-space/PLS-Dataset/code_/training/training_utils.py", line 201, in run
    best_estimator, regressor_params = _optimize_hyperparams(
  File "/gpfs_common/share03/ddomlab/sdehgha2/working-space/main/P1_pls-dataset/pls-dataset-space/PLS-Dataset/code_/training/training_utils.py", line 267, in _optimize_hyperparams
    bayes.fit(X_train, y_train)
  File "/usr/local/usrapps/ddomlab/sdehgha2/pls-dataset-env/lib/python3.10/site-packages/skopt/searchcv.py", line 542, in fit
Traceback (most recent call last):
  File "/usr/local/usrapps/ddomlab/sdehgha2/pls-dataset-env/lib/python3.10/site-packages/joblib/externals/loky/process_executor.py", line 426, in _process_worker
    call_item = call_queue.get(block=True, timeout=timeout)
  File "/usr/local/usrapps/ddomlab/sdehgha2/pls-dataset-env/lib/python3.10/multiprocessing/queues.py", line 108, in get
    if not self._rlock.acquire(block, timeout):
KeyboardInterrupt

During handling of the above exception, another exception occurred:

Traceback (most recent call last):
  File "/usr/local/usrapps/ddomlab/sdehgha2/pls-dataset-env/lib/python3.10/multiprocessing/process.py", line 314, in _bootstrap
    self.run()
  File "/usr/local/usrapps/ddomlab/sdehgha2/pls-dataset-env/lib/python3.10/multiprocessing/process.py", line 108, in run
    self._target(*self._args, **self._kwargs)
  File "/usr/local/usrapps/ddomlab/sdehgha2/pls-dataset-env/lib/python3.10/site-packages/joblib/externals/loky/process_executor.py", line 438, in _process_worker
    previous_tb = traceback.format_exc()
  File "/usr/local/usrapps/ddomlab/sdehgha2/pls-dataset-env/lib/python3.10/traceback.py", line 183, in format_exc
    return "".join(format_exception(*sys.exc_info(), limit=limit, chain=chain))
  File "/usr/local/usrapps/ddomlab/sdehgha2/pls-dataset-env/lib/python3.10/traceback.py", line 135, in format_exception
    te = TracebackException(type(value), value, tb, limit=limit, compact=True)
  File "/usr/local/usrapps/ddomlab/sdehgha2/pls-dataset-env/lib/python3.10/traceback.py", line 502, in __init__
    self.stack = StackSummary.extract(
  File "/usr/local/usrapps/ddomlab/sdehgha2/pls-dataset-env/lib/python3.10/traceback.py", line 353, in extract
    limit = getattr(sys, 'tracebacklimit', None)
KeyboardInterrupt
Traceback (most recent call last):
  File "/usr/local/usrapps/ddomlab/sdehgha2/pls-dataset-env/lib/python3.10/site-packages/joblib/externals/loky/process_executor.py", line 426, in _process_worker
    call_item = call_queue.get(block=True, timeout=timeout)
  File "/usr/local/usrapps/ddomlab/sdehgha2/pls-dataset-env/lib/python3.10/multiprocessing/queues.py", line 108, in get
    if not self._rlock.acquire(block, timeout):
KeyboardInterrupt

During handling of the above exception, another exception occurred:

Traceback (most recent call last):
  File "/usr/local/usrapps/ddomlab/sdehgha2/pls-dataset-env/lib/python3.10/multiprocessing/process.py", line 314, in _bootstrap
    self.run()
  File "/usr/local/usrapps/ddomlab/sdehgha2/pls-dataset-env/lib/python3.10/multiprocessing/process.py", line 108, in run
    self._target(*self._args, **self._kwargs)
  File "/usr/local/usrapps/ddomlab/sdehgha2/pls-dataset-env/lib/python3.10/site-packages/joblib/externals/loky/process_executor.py", line 438, in _process_worker
    previous_tb = traceback.format_exc()
  File "/usr/local/usrapps/ddomlab/sdehgha2/pls-dataset-env/lib/python3.10/traceback.py", line 183, in format_exc
    return "".join(format_exception(*sys.exc_info(), limit=limit, chain=chain))
  File "/usr/local/usrapps/ddomlab/sdehgha2/pls-dataset-env/lib/python3.10/traceback.py", line 135, in format_exception
    te = TracebackException(type(value), value, tb, limit=limit, compact=True)
  File "/usr/local/usrapps/ddomlab/sdehgha2/pls-dataset-env/lib/python3.10/traceback.py", line 502, in __init__
    self.stack = StackSummary.extract(
  File "/usr/local/usrapps/ddomlab/sdehgha2/pls-dataset-env/lib/python3.10/traceback.py", line 370, in extract
    linecache.lazycache(filename, f.f_globals)
  File "/usr/local/usrapps/ddomlab/sdehgha2/pls-dataset-env/lib/python3.10/linecache.py", line 161, in lazycache
    if len(cache[filename]) == 1:
KeyboardInterrupt
    super().fit(X=X, y=y, groups=groups, **fit_params)
  File "/usr/local/usrapps/ddomlab/sdehgha2/pls-dataset-env/lib/python3.10/site-packages/sklearn/base.py", line 1473, in wrapper
    return fit_method(estimator, *args, **kwargs)
  File "/usr/local/usrapps/ddomlab/sdehgha2/pls-dataset-env/lib/python3.10/site-packages/sklearn/model_selection/_search.py", line 1019, in fit
    self._run_search(evaluate_candidates)
  File "/usr/local/usrapps/ddomlab/sdehgha2/pls-dataset-env/lib/python3.10/site-packages/skopt/searchcv.py", line 599, in _run_search
    optim_result, score_name = self._step(
  File "/usr/local/usrapps/ddomlab/sdehgha2/pls-dataset-env/lib/python3.10/site-packages/skopt/searchcv.py", line 453, in _step
    all_results = evaluate_candidates(params_dict)
  File "/usr/local/usrapps/ddomlab/sdehgha2/pls-dataset-env/lib/python3.10/site-packages/sklearn/model_selection/_search.py", line 965, in evaluate_candidates
    out = parallel(
  File "/usr/local/usrapps/ddomlab/sdehgha2/pls-dataset-env/lib/python3.10/site-packages/sklearn/utils/parallel.py", line 74, in __call__
    return super().__call__(iterable_with_config)
  File "/usr/local/usrapps/ddomlab/sdehgha2/pls-dataset-env/lib/python3.10/site-packages/joblib/parallel.py", line 2007, in __call__
    return output if self.return_generator else list(output)
  File "/usr/local/usrapps/ddomlab/sdehgha2/pls-dataset-env/lib/python3.10/site-packages/joblib/parallel.py", line 1703, in _get_outputs
    self._abort()
  File "/usr/local/usrapps/ddomlab/sdehgha2/pls-dataset-env/lib/python3.10/site-packages/joblib/parallel.py", line 1614, in _abort
    backend.abort_everything(ensure_ready=ensure_ready)
  File "/usr/local/usrapps/ddomlab/sdehgha2/pls-dataset-env/lib/python3.10/site-packages/joblib/_parallel_backends.py", line 620, in abort_everything
    self._workers.terminate(kill_workers=True)
  File "/usr/local/usrapps/ddomlab/sdehgha2/pls-dataset-env/lib/python3.10/site-packages/joblib/executor.py", line 75, in terminate
    self.shutdown(kill_workers=kill_workers)
  File "/usr/local/usrapps/ddomlab/sdehgha2/pls-dataset-env/lib/python3.10/site-packages/joblib/externals/loky/process_executor.py", line 1288, in shutdown
    mp.util.debug(f"shutting down executor {self}")
  File "/usr/local/usrapps/ddomlab/sdehgha2/pls-dataset-env/lib/python3.10/multiprocessing/util.py", line 49, in debug
    if _logger:
KeyboardInterrupt
