/usr/local/usrapps/ddomlab/sdehgha2/pls-dataset-env/lib/python3.10/site-packages/skopt/optimizer/optimizer.py:517: UserWarning: The objective has been evaluated at point [0.1, 2000, True, 0.0001, False] before, using random point [0.0005361122355581208, 147, True, 0.0019829670124721145, False]
  warnings.warn(
/usr/local/usrapps/ddomlab/sdehgha2/pls-dataset-env/lib/python3.10/site-packages/skopt/optimizer/optimizer.py:517: UserWarning: The objective has been evaluated at point [0.1, 2000, True, 0.0001, False] before, using random point [0.004175781997968402, 846, True, 0.001455829057507752, False]
  warnings.warn(
/usr/local/usrapps/ddomlab/sdehgha2/pls-dataset-env/lib/python3.10/site-packages/skopt/optimizer/optimizer.py:517: UserWarning: The objective has been evaluated at point [0.1, 2000, True, 0.0001, False] before, using random point [0.00011440306853990915, 1451, True, 0.0003386922831409921, False]
  warnings.warn(
/usr/local/usrapps/ddomlab/sdehgha2/pls-dataset-env/lib/python3.10/site-packages/skopt/optimizer/optimizer.py:517: UserWarning: The objective has been evaluated at point [0.1, 2000, True, 0.0001, False] before, using random point [0.00011440306853990915, 1451, True, 0.0003386922831409921, False]
  warnings.warn(
/usr/local/usrapps/ddomlab/sdehgha2/pls-dataset-env/lib/python3.10/site-packages/skopt/optimizer/optimizer.py:517: UserWarning: The objective has been evaluated at point [0.1, 2000, True, 0.0001, False] before, using random point [0.0005361122355581208, 147, True, 0.0019829670124721145, False]
  warnings.warn(
/usr/local/usrapps/ddomlab/sdehgha2/pls-dataset-env/lib/python3.10/site-packages/skopt/optimizer/optimizer.py:517: UserWarning: The objective has been evaluated at point [0.1, 2000, True, 0.0001, False] before, using random point [0.030204940222346367, 210, True, 0.004374672489510409, False]
  warnings.warn(
/usr/local/usrapps/ddomlab/sdehgha2/pls-dataset-env/lib/python3.10/site-packages/skopt/optimizer/optimizer.py:517: UserWarning: The objective has been evaluated at point [0.1, 2000, True, 0.0001, False] before, using random point [0.0005485310121259326, 65, True, 0.0033272280049609112, False]
  warnings.warn(
/usr/local/usrapps/ddomlab/sdehgha2/pls-dataset-env/lib/python3.10/site-packages/skopt/optimizer/optimizer.py:517: UserWarning: The objective has been evaluated at point [0.1, 2000, True, 0.0001, False] before, using random point [0.002286302059431739, 1398, True, 0.004031955179478319, False]
  warnings.warn(
/usr/local/usrapps/ddomlab/sdehgha2/pls-dataset-env/lib/python3.10/site-packages/skopt/optimizer/optimizer.py:517: UserWarning: The objective has been evaluated at point [0.1, 2000, True, 0.0001, False] before, using random point [0.00011440306853990915, 1451, True, 0.0003386922831409921, False]
  warnings.warn(
/usr/local/usrapps/ddomlab/sdehgha2/pls-dataset-env/lib/python3.10/site-packages/skopt/optimizer/optimizer.py:517: UserWarning: The objective has been evaluated at point [0.1, 2000, True, 0.0001, False] before, using random point [0.08755352292106064, 314, True, 0.007755930867677368, False]
  warnings.warn(
/usr/local/usrapps/ddomlab/sdehgha2/pls-dataset-env/lib/python3.10/site-packages/skopt/optimizer/optimizer.py:517: UserWarning: The objective has been evaluated at point [0.1, 2000, True, 0.0001, False] before, using random point [0.002286302059431739, 1398, True, 0.004031955179478319, False]
  warnings.warn(
/usr/local/usrapps/ddomlab/sdehgha2/pls-dataset-env/lib/python3.10/site-packages/skopt/optimizer/optimizer.py:517: UserWarning: The objective has been evaluated at point [0.1, 2000, True, 0.0001, False] before, using random point [0.0017723394817893464, 245, True, 0.007331744616162472, False]
  warnings.warn(
/usr/local/usrapps/ddomlab/sdehgha2/pls-dataset-env/lib/python3.10/site-packages/skopt/optimizer/optimizer.py:517: UserWarning: The objective has been evaluated at point [0.1, 2000, True, 0.0001, False] before, using random point [0.011601714615769641, 339, True, 0.002754825781769547, False]
  warnings.warn(
/usr/local/usrapps/ddomlab/sdehgha2/pls-dataset-env/lib/python3.10/site-packages/skopt/optimizer/optimizer.py:517: UserWarning: The objective has been evaluated at point [0.1, 2000, True, 0.0001, False] before, using random point [0.00021011725489839564, 310, True, 0.008389719461785435, False]
  warnings.warn(
/usr/local/usrapps/ddomlab/sdehgha2/pls-dataset-env/lib/python3.10/site-packages/skopt/optimizer/optimizer.py:517: UserWarning: The objective has been evaluated at point [0.1, 2000, True, 0.0001, False] before, using random point [0.0005516296047793636, 1456, True, 0.000490750263456121, False]
  warnings.warn(
/usr/local/usrapps/ddomlab/sdehgha2/pls-dataset-env/lib/python3.10/site-packages/skopt/optimizer/optimizer.py:517: UserWarning: The objective has been evaluated at point [0.1, 2000, True, 0.0001, False] before, using random point [0.0017723394817893464, 245, True, 0.007331744616162472, False]
  warnings.warn(
/usr/local/usrapps/ddomlab/sdehgha2/pls-dataset-env/lib/python3.10/site-packages/skopt/optimizer/optimizer.py:517: UserWarning: The objective has been evaluated at point [0.1, 2000, True, 0.01, False] before, using random point [0.0033373950631752696, 76, True, 0.0010722083094807037, False]
  warnings.warn(
/usr/local/usrapps/ddomlab/sdehgha2/pls-dataset-env/lib/python3.10/site-packages/skopt/optimizer/optimizer.py:517: UserWarning: The objective has been evaluated at point [0.1, 2000, True, 0.01, False] before, using random point [0.0005361122355581208, 147, True, 0.0019829670124721145, False]
  warnings.warn(
/usr/local/usrapps/ddomlab/sdehgha2/pls-dataset-env/lib/python3.10/site-packages/skopt/optimizer/optimizer.py:517: UserWarning: The objective has been evaluated at point [0.1, 2000, True, 0.0001, False] before, using random point [0.004175781997968402, 846, True, 0.001455829057507752, False]
  warnings.warn(
/usr/local/usrapps/ddomlab/sdehgha2/pls-dataset-env/lib/python3.10/site-packages/skopt/optimizer/optimizer.py:517: UserWarning: The objective has been evaluated at point [0.1, 2000, True, 0.0001, False] before, using random point [0.0005361122355581208, 147, True, 0.0019829670124721145, False]
  warnings.warn(
/usr/local/usrapps/ddomlab/sdehgha2/pls-dataset-env/lib/python3.10/site-packages/skopt/optimizer/optimizer.py:517: UserWarning: The objective has been evaluated at point [0.1, 2000, True, 0.01, False] before, using random point [0.030204940222346367, 210, True, 0.004374672489510409, False]
  warnings.warn(
/usr/local/usrapps/ddomlab/sdehgha2/pls-dataset-env/lib/python3.10/site-packages/skopt/optimizer/optimizer.py:517: UserWarning: The objective has been evaluated at point [0.1, 2000, True, 0.01, False] before, using random point [0.0005516296047793636, 1456, True, 0.000490750263456121, False]
  warnings.warn(
/usr/local/usrapps/ddomlab/sdehgha2/pls-dataset-env/lib/python3.10/site-packages/skopt/optimizer/optimizer.py:517: UserWarning: The objective has been evaluated at point [0.1, 2000, True, 0.01, False] before, using random point [0.0005516296047793636, 1456, True, 0.000490750263456121, False]
  warnings.warn(
/usr/local/usrapps/ddomlab/sdehgha2/pls-dataset-env/lib/python3.10/site-packages/skopt/optimizer/optimizer.py:517: UserWarning: The objective has been evaluated at point [0.1, 2000, True, 0.0001, False] before, using random point [0.0005485310121259326, 65, True, 0.0033272280049609112, False]
  warnings.warn(
/usr/local/usrapps/ddomlab/sdehgha2/pls-dataset-env/lib/python3.10/site-packages/skopt/optimizer/optimizer.py:517: UserWarning: The objective has been evaluated at point [0.1, 2000, True, 0.01, False] before, using random point [0.0017723394817893464, 245, True, 0.007331744616162472, False]
  warnings.warn(
/usr/local/usrapps/ddomlab/sdehgha2/pls-dataset-env/lib/python3.10/site-packages/skopt/optimizer/optimizer.py:517: UserWarning: The objective has been evaluated at point [0.1, 2000, True, 0.01, False] before, using random point [0.08755352292106064, 314, True, 0.007755930867677368, False]
  warnings.warn(
/usr/local/usrapps/ddomlab/sdehgha2/pls-dataset-env/lib/python3.10/site-packages/skopt/optimizer/optimizer.py:517: UserWarning: The objective has been evaluated at point [0.1, 2000, True, 0.01, False] before, using random point [0.018868126084490407, 781, True, 0.00014231136326775404, False]
  warnings.warn(
/usr/local/usrapps/ddomlab/sdehgha2/pls-dataset-env/lib/python3.10/site-packages/skopt/optimizer/optimizer.py:517: UserWarning: The objective has been evaluated at point [0.1, 2000, True, 0.0001, False] before, using random point [0.004175781997968402, 846, True, 0.001455829057507752, False]
  warnings.warn(
/usr/local/usrapps/ddomlab/sdehgha2/pls-dataset-env/lib/python3.10/site-packages/skopt/optimizer/optimizer.py:517: UserWarning: The objective has been evaluated at point [0.1, 2000, True, 0.0001, False] before, using random point [0.0005361122355581208, 147, True, 0.0019829670124721145, False]
  warnings.warn(
/usr/local/usrapps/ddomlab/sdehgha2/pls-dataset-env/lib/python3.10/site-packages/skopt/optimizer/optimizer.py:517: UserWarning: The objective has been evaluated at point [0.1, 2000, True, 0.0001, False] before, using random point [0.0016904663302597473, 673, True, 0.0016725600189252555, False]
  warnings.warn(
/usr/local/usrapps/ddomlab/sdehgha2/pls-dataset-env/lib/python3.10/site-packages/skopt/optimizer/optimizer.py:517: UserWarning: The objective has been evaluated at point [0.1, 2000, True, 0.0001, False] before, using random point [0.012437097431840618, 70, True, 0.0008460891722563266, False]
  warnings.warn(
/usr/local/usrapps/ddomlab/sdehgha2/pls-dataset-env/lib/python3.10/site-packages/skopt/optimizer/optimizer.py:517: UserWarning: The objective has been evaluated at point [0.1, 2000, True, 0.0001, False] before, using random point [0.008456281592901606, 213, True, 0.0015608471529968563, False]
  warnings.warn(
/usr/local/usrapps/ddomlab/sdehgha2/pls-dataset-env/lib/python3.10/site-packages/skopt/optimizer/optimizer.py:517: UserWarning: The objective has been evaluated at point [0.1, 2000, True, 0.0001, False] before, using random point [0.061101828460700426, 1128, True, 0.0004054634660354319, False]
  warnings.warn(
/usr/local/usrapps/ddomlab/sdehgha2/pls-dataset-env/lib/python3.10/site-packages/skopt/optimizer/optimizer.py:517: UserWarning: The objective has been evaluated at point [0.1, 2000, True, 0.0001, False] before, using random point [0.005681044784263898, 108, True, 0.00019060849974197064, False]
  warnings.warn(
/usr/local/usrapps/ddomlab/sdehgha2/pls-dataset-env/lib/python3.10/site-packages/skopt/optimizer/optimizer.py:517: UserWarning: The objective has been evaluated at point [0.1, 2000, True, 0.0001, False] before, using random point [0.007178868885708944, 1545, True, 0.0008793304720021198, False]
  warnings.warn(
/usr/local/usrapps/ddomlab/sdehgha2/pls-dataset-env/lib/python3.10/site-packages/skopt/optimizer/optimizer.py:517: UserWarning: The objective has been evaluated at point [0.1, 2000, True, 0.01, False] before, using random point [0.0005516296047793636, 1456, True, 0.000490750263456121, False]
  warnings.warn(
/usr/local/usrapps/ddomlab/sdehgha2/pls-dataset-env/lib/python3.10/site-packages/skopt/optimizer/optimizer.py:517: UserWarning: The objective has been evaluated at point [0.1, 2000, True, 0.01, False] before, using random point [0.0005516296047793636, 1456, True, 0.000490750263456121, False]
  warnings.warn(
Process LokyProcess-7:
Process LokyProcess-3:
Process LokyProcess-12:
Process LokyProcess-11:
Process LokyProcess-8:
Process LokyProcess-4:
Traceback (most recent call last):
  File "/usr/local/usrapps/ddomlab/sdehgha2/pls-dataset-env/lib/python3.10/site-packages/sklearn/model_selection/_search.py", line 1019, in fit
    self._run_search(evaluate_candidates)
  File "/usr/local/usrapps/ddomlab/sdehgha2/pls-dataset-env/lib/python3.10/site-packages/skopt/searchcv.py", line 599, in _run_search
    optim_result, score_name = self._step(
  File "/usr/local/usrapps/ddomlab/sdehgha2/pls-dataset-env/lib/python3.10/site-packages/skopt/searchcv.py", line 482, in _step
    return (optimizer.tell(params, [-score for score in local_results]), score_name)
  File "/usr/local/usrapps/ddomlab/sdehgha2/pls-dataset-env/lib/python3.10/site-packages/skopt/optimizer/optimizer.py", line 570, in tell
Traceback (most recent call last):
  File "/usr/local/usrapps/ddomlab/sdehgha2/pls-dataset-env/lib/python3.10/site-packages/joblib/externals/loky/process_executor.py", line 426, in _process_worker
    call_item = call_queue.get(block=True, timeout=timeout)
  File "/usr/local/usrapps/ddomlab/sdehgha2/pls-dataset-env/lib/python3.10/multiprocessing/queues.py", line 108, in get
    if not self._rlock.acquire(block, timeout):
KeyboardInterrupt

During handling of the above exception, another exception occurred:

Traceback (most recent call last):
Traceback (most recent call last):
  File "/usr/local/usrapps/ddomlab/sdehgha2/pls-dataset-env/lib/python3.10/multiprocessing/process.py", line 314, in _bootstrap
    self.run()
  File "/usr/local/usrapps/ddomlab/sdehgha2/pls-dataset-env/lib/python3.10/multiprocessing/process.py", line 108, in run
    self._target(*self._args, **self._kwargs)
  File "/usr/local/usrapps/ddomlab/sdehgha2/pls-dataset-env/lib/python3.10/site-packages/joblib/externals/loky/process_executor.py", line 438, in _process_worker
    previous_tb = traceback.format_exc()
  File "/usr/local/usrapps/ddomlab/sdehgha2/pls-dataset-env/lib/python3.10/traceback.py", line 183, in format_exc
    return "".join(format_exception(*sys.exc_info(), limit=limit, chain=chain))
  File "/usr/local/usrapps/ddomlab/sdehgha2/pls-dataset-env/lib/python3.10/traceback.py", line 135, in format_exception
    te = TracebackException(type(value), value, tb, limit=limit, compact=True)
  File "/usr/local/usrapps/ddomlab/sdehgha2/pls-dataset-env/lib/python3.10/traceback.py", line 502, in __init__
    self.stack = StackSummary.extract(
  File "/usr/local/usrapps/ddomlab/sdehgha2/pls-dataset-env/lib/python3.10/traceback.py", line 353, in extract
    limit = getattr(sys, 'tracebacklimit', None)
  File "/usr/local/usrapps/ddomlab/sdehgha2/pls-dataset-env/lib/python3.10/site-packages/joblib/externals/loky/process_executor.py", line 426, in _process_worker
    call_item = call_queue.get(block=True, timeout=timeout)
KeyboardInterrupt
  File "/usr/local/usrapps/ddomlab/sdehgha2/pls-dataset-env/lib/python3.10/multiprocessing/queues.py", line 108, in get
    if not self._rlock.acquire(block, timeout):
KeyboardInterrupt

During handling of the above exception, another exception occurred:

Traceback (most recent call last):
  File "/usr/local/usrapps/ddomlab/sdehgha2/pls-dataset-env/lib/python3.10/multiprocessing/process.py", line 314, in _bootstrap
    self.run()
  File "/usr/local/usrapps/ddomlab/sdehgha2/pls-dataset-env/lib/python3.10/multiprocessing/process.py", line 108, in run
    self._target(*self._args, **self._kwargs)
  File "/usr/local/usrapps/ddomlab/sdehgha2/pls-dataset-env/lib/python3.10/site-packages/joblib/externals/loky/process_executor.py", line 438, in _process_worker
    previous_tb = traceback.format_exc()
  File "/usr/local/usrapps/ddomlab/sdehgha2/pls-dataset-env/lib/python3.10/traceback.py", line 183, in format_exc
    return "".join(format_exception(*sys.exc_info(), limit=limit, chain=chain))
  File "/usr/local/usrapps/ddomlab/sdehgha2/pls-dataset-env/lib/python3.10/traceback.py", line 135, in format_exception
    te = TracebackException(type(value), value, tb, limit=limit, compact=True)
  File "/usr/local/usrapps/ddomlab/sdehgha2/pls-dataset-env/lib/python3.10/traceback.py", line 502, in __init__
    self.stack = StackSummary.extract(
  File "/usr/local/usrapps/ddomlab/sdehgha2/pls-dataset-env/lib/python3.10/traceback.py", line 353, in extract
    limit = getattr(sys, 'tracebacklimit', None)
KeyboardInterrupt
Traceback (most recent call last):
Traceback (most recent call last):
  File "/usr/local/usrapps/ddomlab/sdehgha2/pls-dataset-env/lib/python3.10/site-packages/joblib/externals/loky/process_executor.py", line 426, in _process_worker
    call_item = call_queue.get(block=True, timeout=timeout)
  File "/usr/local/usrapps/ddomlab/sdehgha2/pls-dataset-env/lib/python3.10/multiprocessing/queues.py", line 108, in get
    if not self._rlock.acquire(block, timeout):
KeyboardInterrupt

During handling of the above exception, another exception occurred:

Traceback (most recent call last):
  File "/usr/local/usrapps/ddomlab/sdehgha2/pls-dataset-env/lib/python3.10/multiprocessing/process.py", line 314, in _bootstrap
    self.run()
  File "/usr/local/usrapps/ddomlab/sdehgha2/pls-dataset-env/lib/python3.10/multiprocessing/process.py", line 108, in run
    self._target(*self._args, **self._kwargs)
  File "/usr/local/usrapps/ddomlab/sdehgha2/pls-dataset-env/lib/python3.10/site-packages/joblib/externals/loky/process_executor.py", line 438, in _process_worker
    previous_tb = traceback.format_exc()
  File "/usr/local/usrapps/ddomlab/sdehgha2/pls-dataset-env/lib/python3.10/traceback.py", line 183, in format_exc
    return "".join(format_exception(*sys.exc_info(), limit=limit, chain=chain))
  File "/usr/local/usrapps/ddomlab/sdehgha2/pls-dataset-env/lib/python3.10/traceback.py", line 135, in format_exception
    te = TracebackException(type(value), value, tb, limit=limit, compact=True)
  File "/usr/local/usrapps/ddomlab/sdehgha2/pls-dataset-env/lib/python3.10/traceback.py", line 502, in __init__
    self.stack = StackSummary.extract(
  File "/usr/local/usrapps/ddomlab/sdehgha2/pls-dataset-env/lib/python3.10/traceback.py", line 379, in extract
    linecache.checkcache(filename)
KeyboardInterrupt
Traceback (most recent call last):
  File "/usr/local/usrapps/ddomlab/sdehgha2/pls-dataset-env/lib/python3.10/site-packages/joblib/externals/loky/process_executor.py", line 426, in _process_worker
    call_item = call_queue.get(block=True, timeout=timeout)
  File "/usr/local/usrapps/ddomlab/sdehgha2/pls-dataset-env/lib/python3.10/multiprocessing/queues.py", line 108, in get
    if not self._rlock.acquire(block, timeout):
KeyboardInterrupt

During handling of the above exception, another exception occurred:

Traceback (most recent call last):
  File "/usr/local/usrapps/ddomlab/sdehgha2/pls-dataset-env/lib/python3.10/multiprocessing/process.py", line 314, in _bootstrap
    self.run()
  File "/usr/local/usrapps/ddomlab/sdehgha2/pls-dataset-env/lib/python3.10/multiprocessing/process.py", line 108, in run
    self._target(*self._args, **self._kwargs)
  File "/usr/local/usrapps/ddomlab/sdehgha2/pls-dataset-env/lib/python3.10/site-packages/joblib/externals/loky/process_executor.py", line 438, in _process_worker
    previous_tb = traceback.format_exc()
  File "/usr/local/usrapps/ddomlab/sdehgha2/pls-dataset-env/lib/python3.10/traceback.py", line 183, in format_exc
    return "".join(format_exception(*sys.exc_info(), limit=limit, chain=chain))
  File "/usr/local/usrapps/ddomlab/sdehgha2/pls-dataset-env/lib/python3.10/traceback.py", line 135, in format_exception
    te = TracebackException(type(value), value, tb, limit=limit, compact=True)
  File "/usr/local/usrapps/ddomlab/sdehgha2/pls-dataset-env/lib/python3.10/traceback.py", line 502, in __init__
    self.stack = StackSummary.extract(
  File "/usr/local/usrapps/ddomlab/sdehgha2/pls-dataset-env/lib/python3.10/traceback.py", line 379, in extract
    linecache.checkcache(filename)
  File "/usr/local/usrapps/ddomlab/sdehgha2/pls-dataset-env/lib/python3.10/linecache.py", line 65, in checkcache
    if len(entry) == 1:
KeyboardInterrupt
  File "/usr/local/usrapps/ddomlab/sdehgha2/pls-dataset-env/lib/python3.10/site-packages/joblib/externals/loky/process_executor.py", line 426, in _process_worker
    call_item = call_queue.get(block=True, timeout=timeout)
  File "/usr/local/usrapps/ddomlab/sdehgha2/pls-dataset-env/lib/python3.10/multiprocessing/queues.py", line 108, in get
    if not self._rlock.acquire(block, timeout):
KeyboardInterrupt

During handling of the above exception, another exception occurred:

Traceback (most recent call last):
  File "/usr/local/usrapps/ddomlab/sdehgha2/pls-dataset-env/lib/python3.10/multiprocessing/process.py", line 314, in _bootstrap
    self.run()
  File "/usr/local/usrapps/ddomlab/sdehgha2/pls-dataset-env/lib/python3.10/multiprocessing/process.py", line 108, in run
    self._target(*self._args, **self._kwargs)
  File "/usr/local/usrapps/ddomlab/sdehgha2/pls-dataset-env/lib/python3.10/site-packages/joblib/externals/loky/process_executor.py", line 438, in _process_worker
    previous_tb = traceback.format_exc()
  File "/usr/local/usrapps/ddomlab/sdehgha2/pls-dataset-env/lib/python3.10/traceback.py", line 183, in format_exc
    return "".join(format_exception(*sys.exc_info(), limit=limit, chain=chain))
  File "/usr/local/usrapps/ddomlab/sdehgha2/pls-dataset-env/lib/python3.10/traceback.py", line 135, in format_exception
    te = TracebackException(type(value), value, tb, limit=limit, compact=True)
  File "/usr/local/usrapps/ddomlab/sdehgha2/pls-dataset-env/lib/python3.10/traceback.py", line 489, in __init__
    def __init__(self, exc_type, exc_value, exc_traceback, *, limit=None,
KeyboardInterrupt
Traceback (most recent call last):
  File "/usr/local/usrapps/ddomlab/sdehgha2/pls-dataset-env/lib/python3.10/site-packages/joblib/externals/loky/process_executor.py", line 426, in _process_worker
    call_item = call_queue.get(block=True, timeout=timeout)
  File "/usr/local/usrapps/ddomlab/sdehgha2/pls-dataset-env/lib/python3.10/multiprocessing/queues.py", line 108, in get
    if not self._rlock.acquire(block, timeout):
KeyboardInterrupt

During handling of the above exception, another exception occurred:

Traceback (most recent call last):
  File "/usr/local/usrapps/ddomlab/sdehgha2/pls-dataset-env/lib/python3.10/multiprocessing/process.py", line 314, in _bootstrap
    self.run()
  File "/usr/local/usrapps/ddomlab/sdehgha2/pls-dataset-env/lib/python3.10/multiprocessing/process.py", line 108, in run
    self._target(*self._args, **self._kwargs)
  File "/usr/local/usrapps/ddomlab/sdehgha2/pls-dataset-env/lib/python3.10/site-packages/joblib/externals/loky/process_executor.py", line 438, in _process_worker
    previous_tb = traceback.format_exc()
  File "/usr/local/usrapps/ddomlab/sdehgha2/pls-dataset-env/lib/python3.10/traceback.py", line 183, in format_exc
    return "".join(format_exception(*sys.exc_info(), limit=limit, chain=chain))
  File "/usr/local/usrapps/ddomlab/sdehgha2/pls-dataset-env/lib/python3.10/traceback.py", line 135, in format_exception
    te = TracebackException(type(value), value, tb, limit=limit, compact=True)
  File "/usr/local/usrapps/ddomlab/sdehgha2/pls-dataset-env/lib/python3.10/traceback.py", line 502, in __init__
    self.stack = StackSummary.extract(
  File "/usr/local/usrapps/ddomlab/sdehgha2/pls-dataset-env/lib/python3.10/traceback.py", line 353, in extract
    limit = getattr(sys, 'tracebacklimit', None)
KeyboardInterrupt
    return self._tell(x, y, fit=fit)
  File "/usr/local/usrapps/ddomlab/sdehgha2/pls-dataset-env/lib/python3.10/site-packages/skopt/optimizer/optimizer.py", line 615, in _tell
    est.fit(self.space.transform(self.Xi), self.yi)
  File "/usr/local/usrapps/ddomlab/sdehgha2/pls-dataset-env/lib/python3.10/site-packages/skopt/learning/gaussian_process/gpr.py", line 203, in fit
    super().fit(X, y)
  File "/usr/local/usrapps/ddomlab/sdehgha2/pls-dataset-env/lib/python3.10/site-packages/sklearn/base.py", line 1473, in wrapper
    return fit_method(estimator, *args, **kwargs)
  File "/usr/local/usrapps/ddomlab/sdehgha2/pls-dataset-env/lib/python3.10/site-packages/sklearn/gaussian_process/_gpr.py", line 325, in fit
    self._constrained_optimization(obj_func, theta_initial, bounds)
  File "/usr/local/usrapps/ddomlab/sdehgha2/pls-dataset-env/lib/python3.10/site-packages/sklearn/gaussian_process/_gpr.py", line 652, in _constrained_optimization
    opt_res = scipy.optimize.minimize(
  File "/usr/local/usrapps/ddomlab/sdehgha2/pls-dataset-env/lib/python3.10/site-packages/scipy/optimize/_minimize.py", line 731, in minimize
    res = _minimize_lbfgsb(fun, x0, args, jac, bounds,
  File "/usr/local/usrapps/ddomlab/sdehgha2/pls-dataset-env/lib/python3.10/site-packages/scipy/optimize/_lbfgsb_py.py", line 407, in _minimize_lbfgsb
    f, g = func_and_grad(x)
  File "/usr/local/usrapps/ddomlab/sdehgha2/pls-dataset-env/lib/python3.10/site-packages/scipy/optimize/_differentiable_functions.py", line 343, in fun_and_grad
    self._update_fun()
  File "/usr/local/usrapps/ddomlab/sdehgha2/pls-dataset-env/lib/python3.10/site-packages/scipy/optimize/_differentiable_functions.py", line 294, in _update_fun
    fx = self._wrapped_fun(self.x)
  File "/usr/local/usrapps/ddomlab/sdehgha2/pls-dataset-env/lib/python3.10/site-packages/scipy/optimize/_differentiable_functions.py", line 20, in wrapped
    fx = fun(np.copy(x), *args)
  File "/usr/local/usrapps/ddomlab/sdehgha2/pls-dataset-env/lib/python3.10/site-packages/scipy/optimize/_optimize.py", line 79, in __call__
    self._compute_if_needed(x, *args)
  File "/usr/local/usrapps/ddomlab/sdehgha2/pls-dataset-env/lib/python3.10/site-packages/scipy/optimize/_optimize.py", line 73, in _compute_if_needed
    fg = self.fun(x, *args)
  File "/usr/local/usrapps/ddomlab/sdehgha2/pls-dataset-env/lib/python3.10/site-packages/sklearn/gaussian_process/_gpr.py", line 297, in obj_func
    lml, grad = self.log_marginal_likelihood(
  File "/usr/local/usrapps/ddomlab/sdehgha2/pls-dataset-env/lib/python3.10/site-packages/sklearn/gaussian_process/_gpr.py", line 573, in log_marginal_likelihood
    kernel.theta = theta
  File "/usr/local/usrapps/ddomlab/sdehgha2/pls-dataset-env/lib/python3.10/site-packages/sklearn/gaussian_process/kernels.py", line 761, in theta
    self.k1.theta = theta[:k1_dims]
  File "/usr/local/usrapps/ddomlab/sdehgha2/pls-dataset-env/lib/python3.10/site-packages/sklearn/gaussian_process/kernels.py", line 761, in theta
    self.k1.theta = theta[:k1_dims]
  File "/usr/local/usrapps/ddomlab/sdehgha2/pls-dataset-env/lib/python3.10/site-packages/sklearn/gaussian_process/kernels.py", line 322, in theta
    for hyperparameter in self.hyperparameters:
  File "/usr/local/usrapps/ddomlab/sdehgha2/pls-dataset-env/lib/python3.10/site-packages/sklearn/gaussian_process/kernels.py", line 280, in hyperparameters
    r = [
  File "/usr/local/usrapps/ddomlab/sdehgha2/pls-dataset-env/lib/python3.10/site-packages/sklearn/gaussian_process/kernels.py", line 281, in <listcomp>
    getattr(self, attr)
  File "/usr/local/usrapps/ddomlab/sdehgha2/pls-dataset-env/lib/python3.10/site-packages/sklearn/gaussian_process/kernels.py", line 1239, in hyperparameter_constant_value
    return Hyperparameter("constant_value", "numeric", self.constant_value_bounds)
  File "/usr/local/usrapps/ddomlab/sdehgha2/pls-dataset-env/lib/python3.10/site-packages/sklearn/gaussian_process/kernels.py", line 124, in __new__
    bounds = np.atleast_2d(bounds)
  File "<__array_function__ internals>", line 180, in atleast_2d
  File "/usr/local/usrapps/ddomlab/sdehgha2/pls-dataset-env/lib/python3.10/site-packages/numpy/core/shape_base.py", line 121, in atleast_2d
    ary = asanyarray(ary)
KeyboardInterrupt

During handling of the above exception, another exception occurred:

Traceback (most recent call last):
  File "/gpfs_common/share03/ddomlab/sdehgha2/working-space/main/P1_pls-dataset/pls-dataset-space/PLS-Dataset/code_/training/hpc_submit_training_Rh/../make_ood_prediction.py", line 125, in <module>
    main_structural_numerical(
  File "/gpfs_common/share03/ddomlab/sdehgha2/working-space/main/P1_pls-dataset/pls-dataset-space/PLS-Dataset/code_/training/hpc_submit_training_Rh/../make_ood_prediction.py", line 59, in main_structural_numerical
    scores, predictions, cluster_y_truth  = train_regressor(
  File "/gpfs_common/share03/ddomlab/sdehgha2/working-space/main/P1_pls-dataset/pls-dataset-space/PLS-Dataset/code_/training/get_ood_split.py", line 75, in train_regressor
    scores, predictions,cluster_y_ture = _prepare_data(
  File "/gpfs_common/share03/ddomlab/sdehgha2/working-space/main/P1_pls-dataset/pls-dataset-space/PLS-Dataset/code_/training/get_ood_split.py", line 146, in _prepare_data
    score, predication, cluster_y_ture  = run_loco_cv(
  File "/gpfs_common/share03/ddomlab/sdehgha2/working-space/main/P1_pls-dataset/pls-dataset-space/PLS-Dataset/code_/training/get_ood_split.py", line 233, in run_loco_cv
    OOD_best_estimator, OOD_regressor_params = optimize_ood_hp(
  File "/gpfs_common/share03/ddomlab/sdehgha2/working-space/main/P1_pls-dataset/pls-dataset-space/PLS-Dataset/code_/training/get_ood_split.py", line 391, in optimize_ood_hp
    bayes.fit(X_t, y_t)
  File "/usr/local/usrapps/ddomlab/sdehgha2/pls-dataset-env/lib/python3.10/site-packages/skopt/searchcv.py", line 542, in fit
    super().fit(X=X, y=y, groups=groups, **fit_params)
  File "/usr/local/usrapps/ddomlab/sdehgha2/pls-dataset-env/lib/python3.10/site-packages/sklearn/base.py", line 1473, in wrapper
    return fit_method(estimator, *args, **kwargs)
  File "/usr/local/usrapps/ddomlab/sdehgha2/pls-dataset-env/lib/python3.10/site-packages/sklearn/model_selection/_search.py", line 947, in fit
    with parallel:
  File "/usr/local/usrapps/ddomlab/sdehgha2/pls-dataset-env/lib/python3.10/site-packages/joblib/parallel.py", line 1354, in __exit__
    self._terminate_and_reset()
  File "/usr/local/usrapps/ddomlab/sdehgha2/pls-dataset-env/lib/python3.10/site-packages/joblib/parallel.py", line 1386, in _terminate_and_reset
    self._backend.terminate()
  File "/usr/local/usrapps/ddomlab/sdehgha2/pls-dataset-env/lib/python3.10/site-packages/joblib/_parallel_backends.py", line 610, in terminate
    self._workers._temp_folder_manager._clean_temporary_resources(
  File "/usr/local/usrapps/ddomlab/sdehgha2/pls-dataset-env/lib/python3.10/site-packages/joblib/_memmapping_reducer.py", line 621, in _clean_temporary_resources
    for filename in os.listdir(temp_folder):
KeyboardInterrupt
